File: xrd/raw/CuOCuCl2.ras
*RAS_DATA_START
*RAS_HEADER_START
*CORR_POS_DB_NAME "C_DteX_ASC-6_15122015"
*CORR_POS_GONIO_RADIUS ""
*CORR_POS_NODE_INDEX01 ""
*CORR_POS_NODE_INDEX02 ""
*CORR_POS_NODE_INDEX03 ""
*CORR_POS_NODE_INDEX04 ""
*CORR_POS_NODE_INDEX05 ""
*CORR_POS_NODE_INDEX06 ""
*CORR_POS_NODE_INDEX07 ""
*CORR_POS_NODE_INDEX08 ""
*CORR_POS_NODE_INDEX09 ""
*CORR_POS_NODE_INDEX10 ""
*CORR_POS_NODE_INDEX11 ""
*CORR_POS_NODE_LABEL01 "Si(111)"
*CORR_POS_NODE_LABEL02 "Si(220)"
*CORR_POS_NODE_LABEL03 "Si(311)"
*CORR_POS_NODE_LABEL04 "Si(400)"
*CORR_POS_NODE_LABEL05 "Si(331)"
*CORR_POS_NODE_LABEL06 "Si(422)"
*CORR_POS_NODE_LABEL07 "Si(511)"
*CORR_POS_NODE_LABEL08 "Si(440)"
*CORR_POS_NODE_LABEL09 "Si(531)"
*CORR_POS_NODE_LABEL10 "Si(620)"
*CORR_POS_NODE_LABEL11 "Si(533)"
*CORR_POS_NODE_POS_CALC01 "28.4137"
*CORR_POS_NODE_POS_CALC02 "47.2707"
*CORR_POS_NODE_POS_CALC03 "56.0883"
*CORR_POS_NODE_POS_CALC04 "69.0934"
*CORR_POS_NODE_POS_CALC05 "76.3385"
*CORR_POS_NODE_POS_CALC06 "87.9915"
*CORR_POS_NODE_POS_CALC07 "94.9137"
*CORR_POS_NODE_POS_CALC08 "106.67"
*CORR_POS_NODE_POS_CALC09 "114.054"
*CORR_POS_NODE_POS_CALC10 "127.508"
*CORR_POS_NODE_POS_CALC11 "136.858"
*CORR_POS_NODE_POS_MEAS01 "28.4844"
*CORR_POS_NODE_POS_MEAS02 "47.3386"
*CORR_POS_NODE_POS_MEAS03 "56.1592"
*CORR_POS_NODE_POS_MEAS04 "69.1708"
*CORR_POS_NODE_POS_MEAS05 "76.4167"
*CORR_POS_NODE_POS_MEAS06 "88.0714"
*CORR_POS_NODE_POS_MEAS07 "94.9948"
*CORR_POS_NODE_POS_MEAS08 "106.756"
*CORR_POS_NODE_POS_MEAS09 "114.134"
*CORR_POS_NODE_POS_MEAS10 "127.59"
*CORR_POS_NODE_POS_MEAS11 "136.946"
*CORR_POS_OPT_ATTR "集中法"
*CORR_POS_PARAM_MU ""
*CORR_POS_PARAM_PL ""
*CORR_POS_SEMODEL_TYPE "0"
*CORR_POS_STANDARD_TYPE ""
*CORR_POS_VALUE_ANALYZER "None"
*CORR_POS_VALUE_CMONO "None"
*CORR_POS_VALUE_IMONO "None"
*CORR_POS_VALUE_IS "0.625deg"
*CORR_POS_VALUE_ISL "10.0mm"
*CORR_POS_VALUE_ISOLLER "2.5deg"
*CORR_POS_VALUE_RS1 "13.0mm"
*CORR_POS_VALUE_RS2 "13.0mm"
*CORR_POS_VALUE_RSOLLER "2.5deg"
*CORR_POS_XG_FOCUS_L ""
*CORR_POS_XG_WAVE_TYPE ""
*CORR_POS_XG_WAVE_VALUE ""
*DISP_FMT_X "%.2f"
*DISP_FMT_Y "%.0f"
*DISP_FULLSCALE "201095.0000000000"
*DISP_LINE_COLOR "255.0000000000"
*DISP_LINE_STYLE "0.0000000000"
*DISP_LINE_WIDTH "0.2500000000"
*DISP_NOTE "Collected Data-2"
*DISP_OFFSET_Y "0.0000000000"
*DISP_PEAKSEARCH_UNIT_Y "cps"
*DISP_RANGE_BOTTOM "0.0000000000"
*DISP_RANGE_LEFT "5.0000000000"
*DISP_RANGE_LOGCUTOFF "0.0100000000"
*DISP_RANGE_RIGHT "90.0000000000"
*DISP_RANGE_TOP "201095.0000000000"
*DISP_SCALE_MODE_Y "0.0000000000"
*DISP_TAB_NAME "Theta/2-Theta"
*DISP_TITLE_Y "Intensity"
*DISP_UNIT_Y "cps"
*DISP_WINDOW_NAME "MSG_MACROENGINE"
*FILE_COMMENT " "
*FILE_MD5 ""
*FILE_MEMO " "
*FILE_OPERATOR "RIGAKU"
*FILE_SAMPLE "CuOCuCl2"
*FILE_TYPE "RAS_RAW"
*FILE_USERGROUP "System Manager"
*FILE_VERSION "1.0000000000"
*HW_ATTACHMENT_ID "ATT1031"
*HW_ATTACHMENT_NAME "6サンプルチェンジャ|ASC-6"
*HW_COUNTER_ID-0 "CUT0025"
*HW_COUNTER_ID-1 "CUT0020"
*HW_COUNTER_ID-2 "CUT0020"
*HW_COUNTER_ID-3 "CMC0021"
*HW_COUNTER_NAME-0 "D/teX Ultra|D/teX Ultra"
*HW_COUNTER_NAME-1 "None|None"
*HW_COUNTER_NAME-2 "None|None"
*HW_COUNTER_NAME-3 "検出器モノクロメータ|Detector monochromator"
*HW_COUNTER_SELECT_NAME "D/teX Ultra|D/teX Ultra"
*HW_GONIOMETER_ID "GON0070"
*HW_GONIOMETER_NAME "MiniFlex 300/600|MiniFlex 300/600"
*HW_GONIOMETER_RADIUS-0 "79.0"
*HW_GONIOMETER_RADIUS-1 "91.5"
*HW_GONIOMETER_RADIUS-2 "150.0"
*HW_GONIOMETER_RADIUS-3 "0"
*HW_GONIOMETER_RADIUS-4 "103.4"
*HW_GONIOMETER_RADIUS-5 "150.0"
*HW_GONIOMETER_RADIUS-6 "46.6"
*HW_GONIOMETER_RADIUS-7 "160.0"
*HW_I_OPT_ID-0 "ISL0021"
*HW_I_OPT_ID-1 "ISO0021"
*HW_I_OPT_NAME-0 "発散スリット|Divergence slit"
*HW_I_OPT_NAME-1 "入射平行スリット|Incident parallel slit"
*HW_R_ATTENUATER_AUTOMODE "0"
*HW_R_OPT_ID-0 "RSS0021"
*HW_R_OPT_ID-1 "RSO0021"
*HW_R_OPT_ID-2 "RRS0021"
*HW_R_OPT_NAME-0 "散乱スリット|Scattering slit"
*HW_R_OPT_NAME-1 "受光平行スリット|Receiving soller slit"
*HW_R_OPT_NAME-2 "受光スリット|Receiving slit"
*HW_SAMPLE_HOLDER_ID "SMP0000"
*HW_SAMPLE_HOLDER_NAME "無し|None"
*HW_XG_CURRENT_MAX "15"
*HW_XG_CURRENT_MIN "2"
*HW_XG_CURRENT_RESOLUTION "1"
*HW_XG_CURRENT_UNIT "mA"
*HW_XG_FOCUS "1mm x 10mm"
*HW_XG_FOCUS_TYPE "Normal"
*HW_XG_ID ""
*HW_XG_NAME "300W/600W 封入管-B|300W/600W Sealed tube-B"
*HW_XG_TARGET_ATOMIC_NUMBER "29.0000000000"
*HW_XG_TARGET_NAME "Cu"
*HW_XG_TYPE "Hermetic"
*HW_XG_VOLTAGE_MAX "40"
*HW_XG_VOLTAGE_MIN "20"
*HW_XG_VOLTAGE_RESOLUTION "1"
*HW_XG_VOLTAGE_UNIT "kV"
*HW_XG_WATT_MAX "0.600"
*HW_XG_WATT_UNIT "kW"
*HW_XG_WAVE_LENGTH_ALPHA1 "1.540593"
*HW_XG_WAVE_LENGTH_ALPHA2 "1.544414"
*HW_XG_WAVE_LENGTH_BETA "1.392250"
*MEAS_COND_AXIS_NAME-0 "Theta/2-Theta"
*MEAS_COND_AXIS_NAME-1 "Spin"
*MEAS_COND_AXIS_NAME-2 "Change"
*MEAS_COND_AXIS_NAME-3 "Soller(inc.)"
*MEAS_COND_AXIS_NAME-4 "IHS"
*MEAS_COND_AXIS_NAME-5 "DS"
*MEAS_COND_AXIS_NAME-6 "SS"
*MEAS_COND_AXIS_NAME-7 "Soller(rec.)"
*MEAS_COND_AXIS_NAME-8 "RS"
*MEAS_COND_AXIS_NAME-9 "Filter"
*MEAS_COND_AXIS_NAME-10 "Monochromator"
*MEAS_COND_AXIS_NAME-11 "PHA"
*MEAS_COND_AXIS_NAME_INTERNAL-0 "TwoThetaTheta"
*MEAS_COND_AXIS_NAME_INTERNAL-1 "Spin"
*MEAS_COND_AXIS_NAME_INTERNAL-2 "Change"
*MEAS_COND_AXIS_NAME_INTERNAL-3 "IncidentSollerSlit"
*MEAS_COND_AXIS_NAME_INTERNAL-4 "IncidentAxdSlit"
*MEAS_COND_AXIS_NAME_INTERNAL-5 "IncidentSlitBox"
*MEAS_COND_AXIS_NAME_INTERNAL-6 "ReceivingSlitBox1"
*MEAS_COND_AXIS_NAME_INTERNAL-7 "ReceivingSollerSlit"
*MEAS_COND_AXIS_NAME_INTERNAL-8 "ReceivingSlitBox2"
*MEAS_COND_AXIS_NAME_INTERNAL-9 "Filter"
*MEAS_COND_AXIS_NAME_INTERNAL-10 "CounterMonochromator"
*MEAS_COND_AXIS_NAME_INTERNAL-11 "PHA"
*MEAS_COND_AXIS_NAME_MAGICNO-0 "268632064.0000000000"
*MEAS_COND_AXIS_NAME_MAGICNO-1 "16842752.0000000000"
*MEAS_COND_AXIS_NAME_MAGICNO-2 "16842752.0000000000"
*MEAS_COND_AXIS_NAME_MAGICNO-3 "20971521.0000000000"
*MEAS_COND_AXIS_NAME_MAGICNO-4 "22020097.0000000000"
*MEAS_COND_AXIS_NAME_MAGICNO-5 "22020097.0000000000"
*MEAS_COND_AXIS_NAME_MAGICNO-6 "23068673.0000000000"
*MEAS_COND_AXIS_NAME_MAGICNO-7 "20971521.0000000000"
*MEAS_COND_AXIS_NAME_MAGICNO-8 "23068673.0000000000"
*MEAS_COND_AXIS_NAME_MAGICNO-9 "20971521.0000000000"
*MEAS_COND_AXIS_NAME_MAGICNO-10 "20971521.0000000000"
*MEAS_COND_AXIS_NAME_MAGICNO-11 "0.0000000000"
*MEAS_COND_AXIS_OFFSET-0 "0.0000000000"
*MEAS_COND_AXIS_OFFSET-1 "-"
*MEAS_COND_AXIS_OFFSET-2 "-"
*MEAS_COND_AXIS_OFFSET-3 "-"
*MEAS_COND_AXIS_OFFSET-4 "-"
*MEAS_COND_AXIS_OFFSET-5 "-"
*MEAS_COND_AXIS_OFFSET-6 "-"
*MEAS_COND_AXIS_OFFSET-7 "-"
*MEAS_COND_AXIS_OFFSET-8 "-"
*MEAS_COND_AXIS_OFFSET-9 "-"
*MEAS_COND_AXIS_OFFSET-10 "-"
*MEAS_COND_AXIS_OFFSET-11 "-"
*MEAS_COND_AXIS_POSITION-0 "92.4250000000"
*MEAS_COND_AXIS_POSITION-1 "0.0000000000"
*MEAS_COND_AXIS_POSITION-2 "3.0000000000"
*MEAS_COND_AXIS_POSITION-3 "2.5deg"
*MEAS_COND_AXIS_POSITION-4 "10.0mm"
*MEAS_COND_AXIS_POSITION-5 "0.625deg"
*MEAS_COND_AXIS_POSITION-6 "13.0mm"
*MEAS_COND_AXIS_POSITION-7 "2.5deg"
*MEAS_COND_AXIS_POSITION-8 "13.0mm"
*MEAS_COND_AXIS_POSITION-9 "K-beta(x2)"
*MEAS_COND_AXIS_POSITION-10 "None"
*MEAS_COND_AXIS_POSITION-11 "40.0000000000"
*MEAS_COND_AXIS_UNIT-0 "deg"
*MEAS_COND_AXIS_UNIT-1 ""
*MEAS_COND_AXIS_UNIT-2 ""
*MEAS_COND_AXIS_UNIT-3 ""
*MEAS_COND_AXIS_UNIT-4 ""
*MEAS_COND_AXIS_UNIT-5 ""
*MEAS_COND_AXIS_UNIT-6 ""
*MEAS_COND_AXIS_UNIT-7 ""
*MEAS_COND_AXIS_UNIT-8 ""
*MEAS_COND_AXIS_UNIT-9 ""
*MEAS_COND_AXIS_UNIT-10 ""
*MEAS_COND_AXIS_UNIT-11 "div"
*MEAS_COND_CORRECTION_SLIT_COUNTERMONO "None"
*MEAS_COND_CORRECTION_SLIT_DS "0.625deg"
*MEAS_COND_CORRECTION_SLIT_FILTER "None"
*MEAS_COND_CORRECTION_SLIT_IHS "10.0mm"
*MEAS_COND_CORRECTION_SLIT_RS "13.0mm"
*MEAS_COND_CORRECTION_SLIT_SOLLER_INC "2.5deg"
*MEAS_COND_CORRECTION_SLIT_SOLLER_REC "2.5deg"
*MEAS_COND_CORRECTION_SLIT_SS "13.0mm"
*MEAS_COND_COUNTER_CNTLOSS_CORR "0.0000000000"
*MEAS_COND_COUNTER_PHABASE "40.0000000000"
*MEAS_COND_COUNTER_PHAWINDOW "15.0000000000"
*MEAS_COND_COUNTER_PHA_UNIT "div"
*MEAS_COND_COUNTER_TAUDIFF "0.2500000000"
*MEAS_COND_COUNTER_TAUINT "0.7500000000"
*MEAS_COND_IRRADIATION_MODE "OFF"
*MEAS_COND_IRRADIATION_WIDTH ""
*MEAS_COND_OPT_ATTR " "
*MEAS_COND_OPT_NAME ""
*MEAS_COND_UNSYMMETRIC_MODE "OFF"
*MEAS_COND_XG_CURRENT "15.0000000000"
*MEAS_COND_XG_VOLTAGE "40.0000000000"
*MEAS_COND_XG_WAVE_TYPE "Ka"
*MEAS_DATA_COUNT "4251.0000000000"
*MEAS_SCAN_AXIS_X "Theta/2-Theta"
*MEAS_SCAN_AXIS_X_INTERNAL "TwoThetaTheta"
*MEAS_SCAN_END_TIME "03/03/17 15:36:38"
*MEAS_SCAN_MODE "CONTINUOUS"
*MEAS_SCAN_MONITOR "0"
*MEAS_SCAN_RESOLUTION_X "0.005"
*MEAS_SCAN_SPEED "5.000"
*MEAS_SCAN_SPEED_UNIT "deg/min"
*MEAS_SCAN_START "5.0000000000"
*MEAS_SCAN_START_TIME "03/03/17 15:18:12"
*MEAS_SCAN_STEP "0.0200000000"
*MEAS_SCAN_STOP "90.0000000000"
*MEAS_SCAN_UNIT_X "deg"
*MEAS_SCAN_UNIT_Y "counts"
*SLIT_SYSTEM "0"
*RAS_HEADER_END
*RAS_INT_START
5.000 345.000 1.000
5.060 338.000 1.000
5.120 336.000 1.000
5.180 359.000 1.000
5.240 321.000 1.000
5.300 359.000 1.000
5.360 280.000 1.000
5.420 329.000 1.000
5.480 339.000 1.000
5.540 295.000 1.000
5.600 303.000 1.000
5.660 313.000 1.000
5.720 294.000 1.000
5.780 307.000 1.000
5.840 294.000 1.000
5.900 279.000 1.000
5.960 302.000 1.000
6.020 290.000 1.000
6.080 267.000 1.000
6.140 294.000 1.000
6.200 274.000 1.000
6.260 301.000 1.000
6.320 284.000 1.000
6.380 274.000 1.000
6.440 290.000 1.000
6.500 256.000 1.000
6.560 295.000 1.000
6.620 268.000 1.000
6.680 271.000 1.000
6.740 267.000 1.000
6.800 265.000 1.000
6.860 278.000 1.000
6.920 274.000 1.000
6.980 268.000 1.000
7.040 261.000 1.000
7.100 280.000 1.000
7.160 252.000 1.000
7.220 283.000 1.000
7.280 254.000 1.000
7.340 275.000 1.000
7.400 261.000 1.000
7.460 282.000 1.000
7.520 258.000 1.000
7.580 259.000 1.000
7.640 264.000 1.000
7.700 266.000 1.000
7.760 271.000 1.000
7.820 290.000 1.000
7.880 269.000 1.000
7.940 244.000 1.000
8.000 269.000 1.000
8.060 248.000 1.000
8.120 261.000 1.000
8.180 254.000 1.000
8.240 265.000 1.000
8.300 237.000 1.000
8.360 270.000 1.000
8.420 237.000 1.000
8.480 274.000 1.000
8.540 260.000 1.000
8.600 267.000 1.000
8.660 271.000 1.000
8.720 270.000 1.000
8.780 276.000 1.000
8.840 254.000 1.000
8.900 255.000 1.000
8.960 276.000 1.000
9.020 281.000 1.000
9.080 272.000 1.000
9.140 270.000 1.000
9.200 259.000 1.000
9.260 246.000 1.000
9.320 275.000 1.000
9.380 286.000 1.000
9.440 261.000 1.000
9.500 272.000 1.000
9.560 279.000 1.000
9.620 277.000 1.000
9.680 268.000 1.000
9.740 281.000 1.000
9.800 277.000 1.000
9.860 272.000 1.000
9.920 263.000 1.000
9.980 270.000 1.000
10.040 271.000 1.000
10.100 264.000 1.000
10.160 272.000 1.000
10.220 271.000 1.000
10.280 279.000 1.000
10.340 277.000 1.000
10.400 286.000 1.000
10.460 287.000 1.000
10.520 280.000 1.000
10.580 264.000 1.000
10.640 277.000 1.000
10.700 256.000 1.000
10.760 285.000 1.000
10.820 288.000 1.000
10.880 296.000 1.000
10.940 275.000 1.000
11.000 288.000 1.000
11.060 270.000 1.000
11.120 276.000 1.000
11.180 302.000 1.000
11.240 289.000 1.000
11.300 275.000 1.000
11.360 273.000 1.000
11.420 289.000 1.000
11.480 283.000 1.000
11.540 261.000 1.000
11.600 242.000 1.000
11.660 259.000 1.000
11.720 254.000 1.000
11.780 264.000 1.000
11.840 267.000 1.000
11.900 274.000 1.000
11.960 272.000 1.000
12.020 286.000 1.000
12.080 268.000 1.000
12.140 270.000 1.000
12.200 278.000 1.000
12.260 268.000 1.000
12.320 263.000 1.000
12.380 268.000 1.000
12.440 250.000 1.000
12.500 253.000 1.000
12.560 263.000 1.000
12.620 242.000 1.000
12.680 249.000 1.000
12.740 255.000 1.000
12.800 257.000 1.000
12.860 248.000 1.000
12.920 268.000 1.000
12.980 251.000 1.000
13.040 272.000 1.000
13.100 247.000 1.000
13.160 258.000 1.000
13.220 240.000 1.000
13.280 241.000 1.000
13.340 234.000 1.000
13.400 238.000 1.000
13.460 246.000 1.000
13.520 249.000 1.000
13.580 235.000 1.000
13.640 249.000 1.000
13.700 254.000 1.000
13.760 242.000 1.000
13.820 229.000 1.000
13.880 256.000 1.000
13.940 245.000 1.000
14.000 240.000 1.000
14.060 226.000 1.000
14.120 229.000 1.000
14.180 217.000 1.000
14.240 240.000 1.000
14.300 219.000 1.000
14.360 235.000 1.000
14.420 246.000 1.000
14.480 232.000 1.000
14.540 235.000 1.000
14.600 224.000 1.000
14.660 247.000 1.000
14.720 218.000 1.000
14.780 215.000 1.000
14.840 248.000 1.000
14.900 227.000 1.000
14.960 241.000 1.000
15.020 223.000 1.000
15.080 227.000 1.000
15.140 248.000 1.000
15.200 224.000 1.000
15.260 233.000 1.000
15.320 227.000 1.000
15.380 235.000 1.000
15.440 227.000 1.000
15.500 247.000 1.000
15.560 222.000 1.000
15.620 219.000 1.000
15.680 220.000 1.000
15.740 233.000 1.000
15.800 227.000 1.000
15.860 212.000 1.000
15.920 239.000 1.000
15.980 209.000 1.000
16.040 220.000 1.000
16.100 214.000 1.000
16.160 229.000 1.000
16.220 216.000 1.000
16.280 205.000 1.000
16.340 236.000 1.000
16.400 223.000 1.000
16.460 200.000 1.000
16.520 222.000 1.000
16.580 208.000 1.000
16.640 235.000 1.000
16.700 209.000 1.000
16.760 212.000 1.000
16.820 213.000 1.000
16.880 231.000 1.000
16.940 226.000 1.000
17.000 223.000 1.000
17.060 222.000 1.000
17.120 217.000 1.000
17.180 227.000 1.000
17.240 216.000 1.000
17.300 220.000 1.000
17.360 230.000 1.000
17.420 215.000 1.000
17.480 220.000 1.000
17.540 204.000 1.000
17.600 206.000 1.000
17.660 207.000 1.000
17.720 189.000 1.000
17.780 232.000 1.000
17.840 216.000 1.000
17.900 216.000 1.000
17.960 216.000 1.000
18.020 210.000 1.000
18.080 193.000 1.000
18.140 199.000 1.000
18.200 228.000 1.000
18.260 198.000 1.000
18.320 213.000 1.000
18.380 223.000 1.000
18.440 209.000 1.000
18.500 202.000 1.000
18.560 198.000 1.000
18.620 211.000 1.000
18.680 205.000 1.000
18.740 209.000 1.000
18.800 214.000 1.000
18.860 191.000 1.000
18.920 214.000 1.000
18.980 231.000 1.000
19.040 239.000 1.000
19.100 252.000 1.000
19.160 223.000 1.000
19.220 214.000 1.000
19.280 189.000 1.000
19.340 189.000 1.000
19.400 179.000 1.000
19.460 195.000 1.000
19.520 197.000 1.000
19.580 213.000 1.000
19.640 210.000 1.000
19.700 194.000 1.000
19.760 200.000 1.000
19.820 207.000 1.000
19.880 217.000 1.000
19.940 193.000 1.000
20.000 211.000 1.000
20.060 205.000 1.000
20.120 196.000 1.000
20.180 209.000 1.000
20.240 204.000 1.000
20.300 192.000 1.000
20.360 204.000 1.000
20.420 208.000 1.000
20.480 192.000 1.000
20.540 189.000 1.000
20.600 189.000 1.000
20.660 186.000 1.000
20.720 198.000 1.000
20.780 205.000 1.000
20.840 183.000 1.000
20.900 206.000 1.000
20.960 194.000 1.000
21.020 161.000 1.000
21.080 180.000 1.000
21.140 192.000 1.000
21.200 191.000 1.000
21.260 194.000 1.000
21.320 182.000 1.000
21.380 194.000 1.000
21.440 185.000 1.000
21.500 180.000 1.000
21.560 184.000 1.000
21.620 183.000 1.000
21.680 187.000 1.000
21.740 206.000 1.000
21.800 196.000 1.000
21.860 195.000 1.000
21.920 190.000 1.000
21.980 192.000 1.000
22.040 192.000 1.000
22.100 187.000 1.000
22.160 196.000 1.000
22.220 196.000 1.000
22.280 199.000 1.000
22.340 208.000 1.000
22.400 189.000 1.000
22.460 186.000 1.000
22.520 174.000 1.000
22.580 194.000 1.000
22.640 187.000 1.000
22.700 175.000 1.000
22.760 197.000 1.000
22.820 184.000 1.000
22.880 198.000 1.000
22.940 176.000 1.000
23.000 175.000 1.000
23.060 199.000 1.000
23.120 174.000 1.000
23.180 182.000 1.000
23.240 184.000 1.000
23.300 203.000 1.000
23.360 189.000 1.000
23.420 199.000 1.000
23.480 185.000 1.000
23.540 192.000 1.000
23.600 201.000 1.000
23.660 200.000 1.000
23.720 214.000 1.000
23.780 212.000 1.000
23.840 195.000 1.000
23.900 191.000 1.000
23.960 211.000 1.000
24.020 199.000 1.000
24.080 202.000 1.000
24.140 204.000 1.000
24.200 193.000 1.000
24.260 194.000 1.000
24.320 192.000 1.000
24.380 183.000 1.000
24.440 184.000 1.000
24.500 179.000 1.000
24.560 164.000 1.000
24.620 175.000 1.000
24.680 185.000 1.000
24.740 179.000 1.000
24.800 195.000 1.000
24.860 172.000 1.000
24.920 186.000 1.000
24.980 182.000 1.000
25.040 167.000 1.000
25.100 185.000 1.000
25.160 184.000 1.000
25.220 179.000 1.000
25.280 184.000 1.000
25.340 165.000 1.000
25.400 189.000 1.000
25.460 186.000 1.000
25.520 181.000 1.000
25.580 186.000 1.000
25.640 194.000 1.000
25.700 193.000 1.000
25.760 201.000 1.000
25.820 205.000 1.000
25.880 187.000 1.000
25.940 193.000 1.000
26.000 173.000 1.000
26.060 169.000 1.000
26.120 194.000 1.000
26.180 183.000 1.000
26.240 162.000 1.000
26.300 159.000 1.000
26.360 175.000 1.000
26.420 167.000 1.000
26.480 172.000 1.000
26.540 173.000 1.000
26.600 178.000 1.000
26.660 181.000 1.000
26.720 196.000 1.000
26.780 193.000 1.000
26.840 166.000 1.000
26.900 191.000 1.000
26.960 197.000 1.000
27.020 183.000 1.000
27.080 185.000 1.000
27.140 182.000 1.000
27.200 195.000 1.000
27.260 198.000 1.000
27.320 204.000 1.000
27.380 208.000 1.000
27.440 193.000 1.000
27.500 186.000 1.000
27.560 191.000 1.000
27.620 186.000 1.000
27.680 170.000 1.000
27.740 191.000 1.000
27.800 176.000 1.000
27.860 172.000 1.000
27.920 162.000 1.000
27.980 179.000 1.000
28.040 189.000 1.000
28.100 165.000 1.000
28.160 173.000 1.000
28.220 179.000 1.000
28.280 192.000 1.000
28.340 189.000 1.000
28.400 211.000 1.000
28.460 205.000 1.000
28.520 203.000 1.000
28.580 194.000 1.000
28.640 208.000 1.000
28.700 206.000 1.000
28.760 233.000 1.000
28.820 195.000 1.000
28.880 218.000 1.000
28.940 215.000 1.000
29.000 210.000 1.000
29.060 204.000 1.000
29.120 217.000 1.000
29.180 209.000 1.000
29.240 221.000 1.000
29.300 197.000 1.000
29.360 216.000 1.000
29.420 220.000 1.000
29.480 210.000 1.000
29.540 206.000 1.000
29.600 217.000 1.000
29.660 199.000 1.000
29.720 199.000 1.000
29.780 203.000 1.000
29.840 187.000 1.000
29.900 216.000 1.000
29.960 192.000 1.000
30.020 205.000 1.000
30.080 204.000 1.000
30.140 208.000 1.000
30.200 250.000 1.000
30.260 248.000 1.000
30.320 251.000 1.000
30.380 245.000 1.000
30.440 249.000 1.000
30.500 221.000 1.000
30.560 222.000 1.000
30.620 257.000 1.000
30.680 261.000 1.000
30.740 292.000 1.000
30.800 315.000 1.000
30.860 358.000 1.000
30.920 361.000 1.000
30.980 364.000 1.000
31.040 375.000 1.000
31.100 401.000 1.000
31.160 406.000 1.000
31.220 467.000 1.000
31.280 547.000 1.000
31.340 627.000 1.000
31.400 746.000 1.000
31.460 888.000 1.000
31.520 1110.000 1.000
31.580 1770.000 1.000
31.640 3437.000 1.000
31.700 8524.000 1.000
31.760 18943.000 1.000
31.820 25156.000 1.000
31.880 18397.000 1.000
31.940 9029.000 1.000
32.000 3170.000 1.000
32.060 1543.000 1.000
32.120 1015.000 1.000
32.180 785.000 1.000
32.240 565.000 1.000
32.300 532.000 1.000
32.360 414.000 1.000
32.420 385.000 1.000
32.480 373.000 1.000
32.540 370.000 1.000
32.600 349.000 1.000
32.660 361.000 1.000
32.720 319.000 1.000
32.780 295.000 1.000
32.840 322.000 1.000
32.900 277.000 1.000
32.960 289.000 1.000
33.020 276.000 1.000
33.080 278.000 1.000
33.140 309.000 1.000
33.200 277.000 1.000
33.260 331.000 1.000
33.320 337.000 1.000
33.380 354.000 1.000
33.440 345.000 1.000
33.500 330.000 1.000
33.560 333.000 1.000
33.620 368.000 1.000
33.680 349.000 1.000
33.740 349.000 1.000
33.800 403.000 1.000
33.860 424.000 1.000
33.920 439.000 1.000
33.980 499.000 1.000
34.040 535.000 1.000
34.100 611.000 1.000
34.160 789.000 1.000
34.220 1054.000 1.000
34.280 1932.000 1.000
34.340 4428.000 1.000
34.400 10834.000 1.000
34.460 17479.000 1.000
34.520 15270.000 1.000
34.580 8857.000 1.000
34.640 3551.000 1.000
34.700 1534.000 1.000
34.760 902.000 1.000
34.820 718.000 1.000
34.880 583.000 1.000
34.940 513.000 1.000
35.000 495.000 1.000
35.060 525.000 1.000
35.120 523.000 1.000
35.180 532.000 1.000
35.240 495.000 1.000
35.300 492.000 1.000
35.360 513.000 1.000
35.420 576.000 1.000
35.480 642.000 1.000
35.540 780.000 1.000
35.600 828.000 1.000
35.660 800.000 1.000
35.720 854.000 1.000
35.780 883.000 1.000
35.840 1008.000 1.000
35.900 1206.000 1.000
35.960 1491.000 1.000
36.020 1967.000 1.000
36.080 3355.000 1.000
36.140 7137.000 1.000
36.200 17277.000 1.000
36.260 34332.000 1.000
36.320 39693.000 1.000
36.380 27952.000 1.000
36.440 14536.000 1.000
36.500 5652.000 1.000
36.560 2724.000 1.000
36.620 1723.000 1.000
36.680 1211.000 1.000
36.740 946.000 1.000
36.800 733.000 1.000
36.860 664.000 1.000
36.920 571.000 1.000
36.980 545.000 1.000
37.040 466.000 1.000
37.100 464.000 1.000
37.160 449.000 1.000
37.220 483.000 1.000
37.280 431.000 1.000
37.340 397.000 1.000
37.400 379.000 1.000
37.460 361.000 1.000
37.520 354.000 1.000
37.580 342.000 1.000
37.640 358.000 1.000
37.700 323.000 1.000
37.760 325.000 1.000
37.820 307.000 1.000
37.880 324.000 1.000
37.940 304.000 1.000
38.000 295.000 1.000
38.060 319.000 1.000
38.120 321.000 1.000
38.180 298.000 1.000
38.240 275.000 1.000
38.300 300.000 1.000
38.360 300.000 1.000
38.420 278.000 1.000
38.480 312.000 1.000
38.540 326.000 1.000
38.600 366.000 1.000
38.660 444.000 1.000
38.720 530.000 1.000
38.780 497.000 1.000
38.840 435.000 1.000
38.900 354.000 1.000
38.960 337.000 1.000
39.020 316.000 1.000
39.080 312.000 1.000
39.140 287.000 1.000
39.200 269.000 1.000
39.260 243.000 1.000
39.320 254.000 1.000
39.380 252.000 1.000
39.440 251.000 1.000
39.500 227.000 1.000
39.560 243.000 1.000
39.620 227.000 1.000
39.680 234.000 1.000
39.740 248.000 1.000
39.800 218.000 1.000
39.860 242.000 1.000
39.920 233.000 1.000
39.980 235.000 1.000
40.040 245.000 1.000
40.100 234.000 1.000
40.160 212.000 1.000
40.220 215.000 1.000
40.280 226.000 1.000
40.340 223.000 1.000
40.400 213.000 1.000
40.460 227.000 1.000
40.520 227.000 1.000
40.580 217.000 1.000
40.640 213.000 1.000
40.700 217.000 1.000
40.760 210.000 1.000
40.820 202.000 1.000
40.880 208.000 1.000
40.940 212.000 1.000
41.000 216.000 1.000
41.060 222.000 1.000
41.120 215.000 1.000
41.180 204.000 1.000
41.240 219.000 1.000
41.300 202.000 1.000
41.360 208.000 1.000
41.420 203.000 1.000
41.480 188.000 1.000
41.540 204.000 1.000
41.600 193.000 1.000
41.660 210.000 1.000
41.720 192.000 1.000
41.780 194.000 1.000
41.840 180.000 1.000
41.900 200.000 1.000
41.960 177.000 1.000
42.020 174.000 1.000
42.080 173.000 1.000
42.140 181.000 1.000
42.200 176.000 1.000
42.260 179.000 1.000
42.320 192.000 1.000
42.380 176.000 1.000
42.440 186.000 1.000
42.500 182.000 1.000
42.560 174.000 1.000
42.620 184.000 1.000
42.680 193.000 1.000
42.740 173.000 1.000
42.800 184.000 1.000
42.860 183.000 1.000
42.920 189.000 1.000
42.980 190.000 1.000
43.040 176.000 1.000
43.100 199.000 1.000
43.160 249.000 1.000
43.220 228.000 1.000
43.280 267.000 1.000
43.340 226.000 1.000
43.400 194.000 1.000
43.460 181.000 1.000
43.520 185.000 1.000
43.580 173.000 1.000
43.640 178.000 1.000
43.700 165.000 1.000
43.760 164.000 1.000
43.820 185.000 1.000
43.880 170.000 1.000
43.940 177.000 1.000
44.000 168.000 1.000
44.060 170.000 1.000
44.120 159.000 1.000
44.180 173.000 1.000
44.240 167.000 1.000
44.300 162.000 1.000
44.360 159.000 1.000
44.420 169.000 1.000
44.480 167.000 1.000
44.540 159.000 1.000
44.600 180.000 1.000
44.660 170.000 1.000
44.720 167.000 1.000
44.780 162.000 1.000
44.840 167.000 1.000
44.900 187.000 1.000
44.960 178.000 1.000
45.020 180.000 1.000
45.080 201.000 1.000
45.140 203.000 1.000
45.200 183.000 1.000
45.260 194.000 1.000
45.320 182.000 1.000
45.380 174.000 1.000
45.440 172.000 1.000
45.500 157.000 1.000
45.560 156.000 1.000
45.620 159.000 1.000
45.680 142.000 1.000
45.740 173.000 1.000
45.800 179.000 1.000
45.860 172.000 1.000
45.920 172.000 1.000
45.980 181.000 1.000
46.040 178.000 1.000
46.100 179.000 1.000
46.160 180.000 1.000
46.220 206.000 1.000
46.280 186.000 1.000
46.340 205.000 1.000
46.400 167.000 1.000
46.460 188.000 1.000
46.520 223.000 1.000
46.580 201.000 1.000
46.640 185.000 1.000
46.700 189.000 1.000
46.760 218.000 1.000
46.820 210.000 1.000
46.880 234.000 1.000
46.940 224.000 1.000
47.000 250.000 1.000
47.060 301.000 1.000
47.120 334.000 1.000
47.180 375.000 1.000
47.240 456.000 1.000
47.300 621.000 1.000
47.360 908.000 1.000
47.420 1640.000 1.000
47.480 3613.000 1.000
47.540 6617.000 1.000
47.600 7858.000 1.000
47.660 6135.000 1.000
47.720 4645.000 1.000
47.780 2419.000 1.000
47.840 1164.000 1.000
47.900 703.000 1.000
47.960 485.000 1.000
48.020 360.000 1.000
48.080 317.000 1.000
48.140 255.000 1.000
48.200 242.000 1.000
48.260 239.000 1.000
48.320 233.000 1.000
48.380 226.000 1.000
48.440 195.000 1.000
48.500 185.000 1.000
48.560 207.000 1.000
48.620 193.000 1.000
48.680 213.000 1.000
48.740 218.000 1.000
48.800 221.000 1.000
48.860 227.000 1.000
48.920 242.000 1.000
48.980 214.000 1.000
49.040 185.000 1.000
49.100 180.000 1.000
49.160 180.000 1.000
49.220 188.000 1.000
49.280 178.000 1.000
49.340 180.000 1.000
49.400 176.000 1.000
49.460 179.000 1.000
49.520 146.000 1.000
49.580 169.000 1.000
49.640 165.000 1.000
49.700 161.000 1.000
49.760 173.000 1.000
49.820 158.000 1.000
49.880 161.000 1.000
49.940 173.000 1.000
50.000 167.000 1.000
50.060 180.000 1.000
50.120 163.000 1.000
50.180 158.000 1.000
50.240 161.000 1.000
50.300 153.000 1.000
50.360 169.000 1.000
50.420 161.000 1.000
50.480 158.000 1.000
50.540 181.000 1.000
50.600 163.000 1.000
50.660 168.000 1.000
50.720 155.000 1.000
50.780 171.000 1.000
50.840 165.000 1.000
50.900 171.000 1.000
50.960 173.000 1.000
51.020 158.000 1.000
51.080 166.000 1.000
51.140 153.000 1.000
51.200 165.000 1.000
51.260 148.000 1.000
51.320 171.000 1.000
51.380 156.000 1.000
51.440 145.000 1.000
51.500 158.000 1.000
51.560 164.000 1.000
51.620 152.000 1.000
51.680 170.000 1.000
51.740 160.000 1.000
51.800 159.000 1.000
51.860 152.000 1.000
51.920 155.000 1.000
51.980 159.000 1.000
52.040 163.000 1.000
52.100 164.000 1.000
52.160 151.000 1.000
52.220 159.000 1.000
52.280 156.000 1.000
52.340 140.000 1.000
52.400 155.000 1.000
52.460 173.000 1.000
52.520 154.000 1.000
52.580 146.000 1.000
52.640 146.000 1.000
52.700 171.000 1.000
52.760 165.000 1.000
52.820 154.000 1.000
52.880 165.000 1.000
52.940 172.000 1.000
53.000 166.000 1.000
53.060 184.000 1.000
53.120 166.000 1.000
53.180 177.000 1.000
53.240 156.000 1.000
53.300 166.000 1.000
53.360 163.000 1.000
53.420 177.000 1.000
53.480 185.000 1.000
53.540 199.000 1.000
53.600 188.000 1.000
53.660 156.000 1.000
53.720 173.000 1.000
53.780 167.000 1.000
53.840 161.000 1.000
53.900 159.000 1.000
53.960 161.000 1.000
54.020 170.000 1.000
54.080 165.000 1.000
54.140 149.000 1.000
54.200 154.000 1.000
54.260 164.000 1.000
54.320 157.000 1.000
54.380 153.000 1.000
54.440 171.000 1.000
54.500 165.000 1.000
54.560 198.000 1.000
54.620 184.000 1.000
54.680 207.000 1.000
54.740 207.000 1.000
54.800 188.000 1.000
54.860 204.000 1.000
54.920 203.000 1.000
54.980 188.000 1.000
55.040 217.000 1.000
55.100 222.000 1.000
55.160 188.000 1.000
55.220 205.000 1.000
55.280 220.000 1.000
55.340 219.000 1.000
55.400 220.000 1.000
55.460 217.000 1.000
55.520 224.000 1.000
55.580 228.000 1.000
55.640 224.000 1.000
55.700 238.000 1.000
55.760 240.000 1.000
55.820 248.000 1.000
55.880 267.000 1.000
55.940 261.000 1.000
56.000 326.000 1.000
56.060 370.000 1.000
56.120 399.000 1.000
56.180 467.000 1.000
56.240 586.000 1.000
56.300 796.000 1.000
56.360 1068.000 1.000
56.420 1633.000 1.000
56.480 3092.000 1.000
56.540 6372.000 1.000
56.600 10265.000 1.000
56.660 10314.000 1.000
56.720 8030.000 1.000
56.780 6674.000 1.000
56.840 4195.000 1.000
56.900 2007.000 1.000
56.960 1122.000 1.000
57.020 729.000 1.000
57.080 542.000 1.000
57.140 429.000 1.000
57.200 371.000 1.000
57.260 331.000 1.000
57.320 288.000 1.000
57.380 276.000 1.000
57.440 261.000 1.000
57.500 242.000 1.000
57.560 251.000 1.000
57.620 238.000 1.000
57.680 226.000 1.000
57.740 210.000 1.000
57.800 213.000 1.000
57.860 230.000 1.000
57.920 215.000 1.000
57.980 216.000 1.000
58.040 201.000 1.000
58.100 191.000 1.000
58.160 208.000 1.000
58.220 223.000 1.000
58.280 206.000 1.000
58.340 203.000 1.000
58.400 227.000 1.000
58.460 210.000 1.000
58.520 205.000 1.000
58.580 193.000 1.000
58.640 203.000 1.000
58.700 180.000 1.000
58.760 189.000 1.000
58.820 202.000 1.000
58.880 181.000 1.000
58.940 184.000 1.000
59.000 187.000 1.000
59.060 183.000 1.000
59.120 178.000 1.000
59.180 205.000 1.000
59.240 175.000 1.000
59.300 177.000 1.000
59.360 184.000 1.000
59.420 193.000 1.000
59.480 184.000 1.000
59.540 164.000 1.000
59.600 190.000 1.000
59.660 191.000 1.000
59.720 173.000 1.000
59.780 200.000 1.000
59.840 179.000 1.000
59.900 175.000 1.000
59.960 177.000 1.000
60.020 163.000 1.000
60.080 188.000 1.000
60.140 185.000 1.000
60.200 185.000 1.000
60.260 212.000 1.000
60.320 192.000 1.000
60.380 195.000 1.000
60.440 190.000 1.000
60.500 218.000 1.000
60.560 191.000 1.000
60.620 202.000 1.000
60.680 209.000 1.000
60.740 201.000 1.000
60.800 202.000 1.000
60.860 220.000 1.000
60.920 212.000 1.000
60.980 212.000 1.000
61.040 196.000 1.000
61.100 221.000 1.000
61.160 208.000 1.000
61.220 218.000 1.000
61.280 224.000 1.000
61.340 225.000 1.000
61.400 230.000 1.000
61.460 225.000 1.000
61.520 254.000 1.000
61.580 273.000 1.000
61.640 242.000 1.000
61.700 266.000 1.000
61.760 237.000 1.000
61.820 243.000 1.000
61.880 252.000 1.000
61.940 228.000 1.000
62.000 247.000 1.000
62.060 250.000 1.000
62.120 263.000 1.000
62.180 267.000 1.000
62.240 319.000 1.000
62.300 343.000 1.000
62.360 386.000 1.000
62.420 448.000 1.000
62.480 550.000 1.000
62.540 698.000 1.000
62.600 965.000 1.000
62.660 1385.000 1.000
62.720 2391.000 1.000
62.780 4406.000 1.000
62.840 7741.000 1.000
62.900 8830.000 1.000
62.960 6888.000 1.000
63.020 5905.000 1.000
63.080 4971.000 1.000
63.140 3015.000 1.000
63.200 1569.000 1.000
63.260 975.000 1.000
63.320 652.000 1.000
63.380 523.000 1.000
63.440 431.000 1.000
63.500 356.000 1.000
63.560 325.000 1.000
63.620 293.000 1.000
63.680 271.000 1.000
63.740 271.000 1.000
63.800 242.000 1.000
63.860 259.000 1.000
63.920 239.000 1.000
63.980 247.000 1.000
64.040 216.000 1.000
64.100 236.000 1.000
64.160 224.000 1.000
64.220 212.000 1.000
64.280 236.000 1.000
64.340 232.000 1.000
64.400 249.000 1.000
64.460 208.000 1.000
64.520 211.000 1.000
64.580 202.000 1.000
64.640 209.000 1.000
64.700 223.000 1.000
64.760 210.000 1.000
64.820 197.000 1.000
64.880 184.000 1.000
64.940 208.000 1.000
65.000 189.000 1.000
65.060 205.000 1.000
65.120 217.000 1.000
65.180 213.000 1.000
65.240 220.000 1.000
65.300 215.000 1.000
65.360 210.000 1.000
65.420 212.000 1.000
65.480 235.000 1.000
65.540 230.000 1.000
65.600 230.000 1.000
65.660 236.000 1.000
65.720 250.000 1.000
65.780 248.000 1.000
65.840 255.000 1.000
65.900 307.000 1.000
65.960 290.000 1.000
66.020 324.000 1.000
66.080 346.000 1.000
66.140 377.000 1.000
66.200 498.000 1.000
66.260 689.000 1.000
66.320 1192.000 1.000
66.380 1489.000 1.000
66.440 1437.000 1.000
66.500 1172.000 1.000
66.560 1078.000 1.000
66.620 893.000 1.000
66.680 579.000 1.000
66.740 422.000 1.000
66.800 345.000 1.000
66.860 289.000 1.000
66.920 307.000 1.000
66.980 264.000 1.000
67.040 255.000 1.000
67.100 292.000 1.000
67.160 268.000 1.000
67.220 291.000 1.000
67.280 289.000 1.000
67.340 334.000 1.000
67.400 380.000 1.000
67.460 414.000 1.000
67.520 490.000 1.000
67.580 604.000 1.000
67.640 726.000 1.000
67.700 965.000 1.000
67.760 1499.000 1.000
67.820 2517.000 1.000
67.880 4608.000 1.000
67.940 6689.000 1.000
68.000 6629.000 1.000
68.060 5195.000 1.000
68.120 4673.000 1.000
68.180 3944.000 1.000
68.240 2593.000 1.000
68.300 1491.000 1.000
68.360 961.000 1.000
68.420 653.000 1.000
68.480 548.000 1.000
68.540 479.000 1.000
68.600 443.000 1.000
68.660 428.000 1.000
68.720 465.000 1.000
68.780 511.000 1.000
68.840 657.000 1.000
68.900 873.000 1.000
68.960 1448.000 1.000
69.020 2438.000 1.000
69.080 3443.000 1.000
69.140 3314.000 1.000
69.200 2576.000 1.000
69.260 2453.000 1.000
69.320 2054.000 1.000
69.380 1409.000 1.000
69.440 842.000 1.000
69.500 549.000 1.000
69.560 410.000 1.000
69.620 337.000 1.000
69.680 297.000 1.000
69.740 282.000 1.000
69.800 257.000 1.000
69.860 234.000 1.000
69.920 228.000 1.000
69.980 208.000 1.000
70.040 215.000 1.000
70.100 213.000 1.000
70.160 203.000 1.000
70.220 208.000 1.000
70.280 190.000 1.000
70.340 197.000 1.000
70.400 207.000 1.000
70.460 201.000 1.000
70.520 180.000 1.000
70.580 219.000 1.000
70.640 220.000 1.000
70.700 185.000 1.000
70.760 189.000 1.000
70.820 171.000 1.000
70.880 183.000 1.000
70.940 191.000 1.000
71.000 180.000 1.000
71.060 179.000 1.000
71.120 159.000 1.000
71.180 177.000 1.000
71.240 180.000 1.000
71.300 188.000 1.000
71.360 158.000 1.000
71.420 164.000 1.000
71.480 164.000 1.000
71.540 181.000 1.000
71.600 163.000 1.000
71.660 171.000 1.000
71.720 187.000 1.000
71.780 175.000 1.000
71.840 162.000 1.000
71.900 182.000 1.000
71.960 185.000 1.000
72.020 183.000 1.000
72.080 170.000 1.000
72.140 198.000 1.000
72.200 202.000 1.000
72.260 206.000 1.000
72.320 228.000 1.000
72.380 265.000 1.000
72.440 344.000 1.000
72.500 475.000 1.000
72.560 690.000 1.000
72.620 672.000 1.000
72.680 537.000 1.000
72.740 493.000 1.000
72.800 467.000 1.000
72.860 358.000 1.000
72.920 271.000 1.000
72.980 216.000 1.000
73.040 197.000 1.000
73.100 174.000 1.000
73.160 177.000 1.000
73.220 174.000 1.000
73.280 170.000 1.000
73.340 160.000 1.000
73.400 156.000 1.000
73.460 160.000 1.000
73.520 166.000 1.000
73.580 180.000 1.000
73.640 149.000 1.000
73.700 158.000 1.000
73.760 151.000 1.000
73.820 178.000 1.000
73.880 142.000 1.000
73.940 169.000 1.000
74.000 146.000 1.000
74.060 162.000 1.000
74.120 165.000 1.000
74.180 145.000 1.000
74.240 164.000 1.000
74.300 162.000 1.000
74.360 162.000 1.000
74.420 165.000 1.000
74.480 175.000 1.000
74.540 162.000 1.000
74.600 151.000 1.000
74.660 157.000 1.000
74.720 162.000 1.000
74.780 152.000 1.000
74.840 160.000 1.000
74.900 177.000 1.000
74.960 171.000 1.000
75.020 185.000 1.000
75.080 166.000 1.000
75.140 177.000 1.000
75.200 166.000 1.000
75.260 180.000 1.000
75.320 183.000 1.000
75.380 167.000 1.000
75.440 155.000 1.000
75.500 163.000 1.000
75.560 149.000 1.000
75.620 162.000 1.000
75.680 152.000 1.000
75.740 153.000 1.000
75.800 155.000 1.000
75.860 145.000 1.000
75.920 146.000 1.000
75.980 163.000 1.000
76.040 143.000 1.000
76.100 153.000 1.000
76.160 154.000 1.000
76.220 158.000 1.000
76.280 166.000 1.000
76.340 175.000 1.000
76.400 174.000 1.000
76.460 181.000 1.000
76.520 208.000 1.000
76.580 205.000 1.000
76.640 235.000 1.000
76.700 297.000 1.000
76.760 353.000 1.000
76.820 509.000 1.000
76.880 758.000 1.000
76.940 1086.000 1.000
77.000 1150.000 1.000
77.060 899.000 1.000
77.120 772.000 1.000
77.180 711.000 1.000
77.240 658.000 1.000
77.300 461.000 1.000
77.360 307.000 1.000
77.420 233.000 1.000
77.480 187.000 1.000
77.540 206.000 1.000
77.600 157.000 1.000
77.660 152.000 1.000
77.720 167.000 1.000
77.780 158.000 1.000
77.840 145.000 1.000
77.900 156.000 1.000
77.960 124.000 1.000
78.020 140.000 1.000
78.080 133.000 1.000
78.140 151.000 1.000
78.200 156.000 1.000
78.260 147.000 1.000
78.320 131.000 1.000
78.380 150.000 1.000
78.440 152.000 1.000
78.500 126.000 1.000
78.560 131.000 1.000
78.620 151.000 1.000
78.680 141.000 1.000
78.740 149.000 1.000
78.800 146.000 1.000
78.860 133.000 1.000
78.920 126.000 1.000
78.980 152.000 1.000
79.040 140.000 1.000
79.100 148.000 1.000
79.160 147.000 1.000
79.220 152.000 1.000
79.280 138.000 1.000
79.340 147.000 1.000
79.400 129.000 1.000
79.460 151.000 1.000
79.520 150.000 1.000
79.580 146.000 1.000
79.640 145.000 1.000
79.700 138.000 1.000
79.760 147.000 1.000
79.820 131.000 1.000
79.880 134.000 1.000
79.940 131.000 1.000
80.000 132.000 1.000
80.060 140.000 1.000
80.120 133.000 1.000
80.180 145.000 1.000
80.240 135.000 1.000
80.300 144.000 1.000
80.360 127.000 1.000
80.420 130.000 1.000
80.480 138.000 1.000
80.540 147.000 1.000
80.600 142.000 1.000
80.660 138.000 1.000
80.720 140.000 1.000
80.780 150.000 1.000
80.840 151.000 1.000
80.900 157.000 1.000
80.960 169.000 1.000
81.020 168.000 1.000
81.080 195.000 1.000
81.140 238.000 1.000
81.200 247.000 1.000
81.260 329.000 1.000
81.320 460.000 1.000
81.380 586.000 1.000
81.440 592.000 1.000
81.500 469.000 1.000
81.560 432.000 1.000
81.620 425.000 1.000
81.680 383.000 1.000
81.740 305.000 1.000
81.800 228.000 1.000
81.860 197.000 1.000
81.920 183.000 1.000
81.980 154.000 1.000
82.040 136.000 1.000
82.100 154.000 1.000
82.160 155.000 1.000
82.220 138.000 1.000
82.280 146.000 1.000
82.340 148.000 1.000
82.400 150.000 1.000
82.460 146.000 1.000
82.520 132.000 1.000
82.580 157.000 1.000
82.640 123.000 1.000
82.700 153.000 1.000
82.760 135.000 1.000
82.820 137.000 1.000
82.880 149.000 1.000
82.940 144.000 1.000
83.000 142.000 1.000
83.060 140.000 1.000
83.120 141.000 1.000
83.180 137.000 1.000
83.240 136.000 1.000
83.300 152.000 1.000
83.360 141.000 1.000
83.420 125.000 1.000
83.480 132.000 1.000
83.540 148.000 1.000
83.600 152.000 1.000
83.660 144.000 1.000
83.720 119.000 1.000
83.780 143.000 1.000
83.840 153.000 1.000
83.900 151.000 1.000
83.960 145.000 1.000
84.020 134.000 1.000
84.080 141.000 1.000
84.140 138.000 1.000
84.200 134.000 1.000
84.260 145.000 1.000
84.320 135.000 1.000
84.380 135.000 1.000
84.440 130.000 1.000
84.500 128.000 1.000
84.560 133.000 1.000
84.620 141.000 1.000
84.680 124.000 1.000
84.740 121.000 1.000
84.800 108.000 1.000
84.860 128.000 1.000
84.920 144.000 1.000
84.980 134.000 1.000
85.040 123.000 1.000
85.100 123.000 1.000
85.160 133.000 1.000
85.220 132.000 1.000
85.280 110.000 1.000
85.340 126.000 1.000
85.400 140.000 1.000
85.460 130.000 1.000
85.520 138.000 1.000
85.580 139.000 1.000
85.640 120.000 1.000
85.700 134.000 1.000
85.760 135.000 1.000
85.820 144.000 1.000
85.880 142.000 1.000
85.940 158.000 1.000
86.000 127.000 1.000
86.060 141.000 1.000
86.120 130.000 1.000
86.180 119.000 1.000
86.240 132.000 1.000
86.300 131.000 1.000
86.360 122.000 1.000
86.420 110.000 1.000
86.480 126.000 1.000
86.540 134.000 1.000
86.600 138.000 1.000
86.660 122.000 1.000
86.720 140.000 1.000
86.780 134.000 1.000
86.840 142.000 1.000
86.900 150.000 1.000
86.960 148.000 1.000
87.020 129.000 1.000
87.080 118.000 1.000
87.140 130.000 1.000
87.200 136.000 1.000
87.260 127.000 1.000
87.320 150.000 1.000
87.380 149.000 1.000
87.440 153.000 1.000
87.500 140.000 1.000
87.560 132.000 1.000
87.620 133.000 1.000
87.680 157.000 1.000
87.740 134.000 1.000
87.800 130.000 1.000
87.860 138.000 1.000
87.920 131.000 1.000
87.980 145.000 1.000
88.040 138.000 1.000
88.100 132.000 1.000
88.160 123.000 1.000
88.220 142.000 1.000
88.280 152.000 1.000
88.340 138.000 1.000
88.400 131.000 1.000
88.460 142.000 1.000
88.520 147.000 1.000
88.580 160.000 1.000
88.640 181.000 1.000
88.700 169.000 1.000
88.760 164.000 1.000
88.820 178.000 1.000
88.880 175.000 1.000
88.940 200.000 1.000
89.000 198.000 1.000
89.060 238.000 1.000
89.120 234.000 1.000
89.180 300.000 1.000
89.240 304.000 1.000
89.300 383.000 1.000
89.360 515.000 1.000
89.420 731.000 1.000
89.480 1090.000 1.000
89.540 1537.000 1.000
89.600 1922.000 1.000
89.660 1899.000 1.000
89.720 1510.000 1.000
89.780 1197.000 1.000
89.840 1260.000 1.000
89.900 1237.000 1.000
89.960 1219.000 1.000
90.000 1219.000 1.000
*RAS_INT_END
*RAS_DATA_END