File: xrd/raw/ZnOFeCl3.ras
*RAS_DATA_START
*RAS_HEADER_START
*CORR_POS_DB_NAME "C_DteX_ASC-6_15122015"
*CORR_POS_GONIO_RADIUS ""
*CORR_POS_NODE_INDEX01 ""
*CORR_POS_NODE_INDEX02 ""
*CORR_POS_NODE_INDEX03 ""
*CORR_POS_NODE_INDEX04 ""
*CORR_POS_NODE_INDEX05 ""
*CORR_POS_NODE_INDEX06 ""
*CORR_POS_NODE_INDEX07 ""
*CORR_POS_NODE_INDEX08 ""
*CORR_POS_NODE_INDEX09 ""
*CORR_POS_NODE_INDEX10 ""
*CORR_POS_NODE_INDEX11 ""
*CORR_POS_NODE_LABEL01 "Si(111)"
*CORR_POS_NODE_LABEL02 "Si(220)"
*CORR_POS_NODE_LABEL03 "Si(311)"
*CORR_POS_NODE_LABEL04 "Si(400)"
*CORR_POS_NODE_LABEL05 "Si(331)"
*CORR_POS_NODE_LABEL06 "Si(422)"
*CORR_POS_NODE_LABEL07 "Si(511)"
*CORR_POS_NODE_LABEL08 "Si(440)"
*CORR_POS_NODE_LABEL09 "Si(531)"
*CORR_POS_NODE_LABEL10 "Si(620)"
*CORR_POS_NODE_LABEL11 "Si(533)"
*CORR_POS_NODE_POS_CALC01 "28.4137"
*CORR_POS_NODE_POS_CALC02 "47.2707"
*CORR_POS_NODE_POS_CALC03 "56.0883"
*CORR_POS_NODE_POS_CALC04 "69.0934"
*CORR_POS_NODE_POS_CALC05 "76.3385"
*CORR_POS_NODE_POS_CALC06 "87.9915"
*CORR_POS_NODE_POS_CALC07 "94.9137"
*CORR_POS_NODE_POS_CALC08 "106.67"
*CORR_POS_NODE_POS_CALC09 "114.054"
*CORR_POS_NODE_POS_CALC10 "127.508"
*CORR_POS_NODE_POS_CALC11 "136.858"
*CORR_POS_NODE_POS_MEAS01 "28.4844"
*CORR_POS_NODE_POS_MEAS02 "47.3386"
*CORR_POS_NODE_POS_MEAS03 "56.1592"
*CORR_POS_NODE_POS_MEAS04 "69.1708"
*CORR_POS_NODE_POS_MEAS05 "76.4167"
*CORR_POS_NODE_POS_MEAS06 "88.0714"
*CORR_POS_NODE_POS_MEAS07 "94.9948"
*CORR_POS_NODE_POS_MEAS08 "106.756"
*CORR_POS_NODE_POS_MEAS09 "114.134"
*CORR_POS_NODE_POS_MEAS10 "127.59"
*CORR_POS_NODE_POS_MEAS11 "136.946"
*CORR_POS_OPT_ATTR "集中法"
*CORR_POS_PARAM_MU ""
*CORR_POS_PARAM_PL ""
*CORR_POS_SEMODEL_TYPE "0"
*CORR_POS_STANDARD_TYPE ""
*CORR_POS_VALUE_ANALYZER "None"
*CORR_POS_VALUE_CMONO "None"
*CORR_POS_VALUE_IMONO "None"
*CORR_POS_VALUE_IS "0.625deg"
*CORR_POS_VALUE_ISL "10.0mm"
*CORR_POS_VALUE_ISOLLER "2.5deg"
*CORR_POS_VALUE_RS1 "13.0mm"
*CORR_POS_VALUE_RS2 "13.0mm"
*CORR_POS_VALUE_RSOLLER "2.5deg"
*CORR_POS_XG_FOCUS_L ""
*CORR_POS_XG_WAVE_TYPE ""
*CORR_POS_XG_WAVE_VALUE ""
*DISP_FMT_X "%.2f"
*DISP_FMT_Y "%.0f"
*DISP_FULLSCALE "31120.0000000000"
*DISP_LINE_COLOR "255.0000000000"
*DISP_LINE_STYLE "0.0000000000"
*DISP_LINE_WIDTH "0.2500000000"
*DISP_NOTE "Collected Data-3"
*DISP_OFFSET_Y "0.0000000000"
*DISP_PEAKSEARCH_UNIT_Y "cps"
*DISP_RANGE_BOTTOM "0.0000000000"
*DISP_RANGE_LEFT "5.0000000000"
*DISP_RANGE_LOGCUTOFF "0.0100000000"
*DISP_RANGE_RIGHT "90.0000000000"
*DISP_RANGE_TOP "31120.0000000000"
*DISP_SCALE_MODE_Y "0.0000000000"
*DISP_TAB_NAME "Theta/2-Theta"
*DISP_TITLE_Y "Intensity"
*DISP_UNIT_Y "cps"
*DISP_WINDOW_NAME "MSG_MACROENGINE"
*FILE_COMMENT " "
*FILE_MD5 ""
*FILE_MEMO " "
*FILE_OPERATOR "RIGAKU"
*FILE_SAMPLE "ZnOFeCl3"
*FILE_TYPE "RAS_RAW"
*FILE_USERGROUP "System Manager"
*FILE_VERSION "1.0000000000"
*HW_ATTACHMENT_ID "ATT1031"
*HW_ATTACHMENT_NAME "6サンプルチェンジャ|ASC-6"
*HW_COUNTER_ID-0 "CUT0025"
*HW_COUNTER_ID-1 "CUT0020"
*HW_COUNTER_ID-2 "CUT0020"
*HW_COUNTER_ID-3 "CMC0021"
*HW_COUNTER_NAME-0 "D/teX Ultra|D/teX Ultra"
*HW_COUNTER_NAME-1 "None|None"
*HW_COUNTER_NAME-2 "None|None"
*HW_COUNTER_NAME-3 "検出器モノクロメータ|Detector monochromator"
*HW_COUNTER_SELECT_NAME "D/teX Ultra|D/teX Ultra"
*HW_GONIOMETER_ID "GON0070"
*HW_GONIOMETER_NAME "MiniFlex 300/600|MiniFlex 300/600"
*HW_GONIOMETER_RADIUS-0 "79.0"
*HW_GONIOMETER_RADIUS-1 "91.5"
*HW_GONIOMETER_RADIUS-2 "150.0"
*HW_GONIOMETER_RADIUS-3 "0"
*HW_GONIOMETER_RADIUS-4 "103.4"
*HW_GONIOMETER_RADIUS-5 "150.0"
*HW_GONIOMETER_RADIUS-6 "46.6"
*HW_GONIOMETER_RADIUS-7 "160.0"
*HW_I_OPT_ID-0 "ISL0021"
*HW_I_OPT_ID-1 "ISO0021"
*HW_I_OPT_NAME-0 "発散スリット|Divergence slit"
*HW_I_OPT_NAME-1 "入射平行スリット|Incident parallel slit"
*HW_R_ATTENUATER_AUTOMODE "0"
*HW_R_OPT_ID-0 "RSS0021"
*HW_R_OPT_ID-1 "RSO0021"
*HW_R_OPT_ID-2 "RRS0021"
*HW_R_OPT_NAME-0 "散乱スリット|Scattering slit"
*HW_R_OPT_NAME-1 "受光平行スリット|Receiving soller slit"
*HW_R_OPT_NAME-2 "受光スリット|Receiving slit"
*HW_SAMPLE_HOLDER_ID "SMP0000"
*HW_SAMPLE_HOLDER_NAME "無し|None"
*HW_XG_CURRENT_MAX "15"
*HW_XG_CURRENT_MIN "2"
*HW_XG_CURRENT_RESOLUTION "1"
*HW_XG_CURRENT_UNIT "mA"
*HW_XG_FOCUS "1mm x 10mm"
*HW_XG_FOCUS_TYPE "Normal"
*HW_XG_ID ""
*HW_XG_NAME "300W/600W 封入管-B|300W/600W Sealed tube-B"
*HW_XG_TARGET_ATOMIC_NUMBER "29.0000000000"
*HW_XG_TARGET_NAME "Cu"
*HW_XG_TYPE "Hermetic"
*HW_XG_VOLTAGE_MAX "40"
*HW_XG_VOLTAGE_MIN "20"
*HW_XG_VOLTAGE_RESOLUTION "1"
*HW_XG_VOLTAGE_UNIT "kV"
*HW_XG_WATT_MAX "0.600"
*HW_XG_WATT_UNIT "kW"
*HW_XG_WAVE_LENGTH_ALPHA1 "1.540593"
*HW_XG_WAVE_LENGTH_ALPHA2 "1.544414"
*HW_XG_WAVE_LENGTH_BETA "1.392250"
*MEAS_COND_AXIS_NAME-0 "Theta/2-Theta"
*MEAS_COND_AXIS_NAME-1 "Spin"
*MEAS_COND_AXIS_NAME-2 "Change"
*MEAS_COND_AXIS_NAME-3 "Soller(inc.)"
*MEAS_COND_AXIS_NAME-4 "IHS"
*MEAS_COND_AXIS_NAME-5 "DS"
*MEAS_COND_AXIS_NAME-6 "SS"
*MEAS_COND_AXIS_NAME-7 "Soller(rec.)"
*MEAS_COND_AXIS_NAME-8 "RS"
*MEAS_COND_AXIS_NAME-9 "Filter"
*MEAS_COND_AXIS_NAME-10 "Monochromator"
*MEAS_COND_AXIS_NAME-11 "PHA"
*MEAS_COND_AXIS_NAME_INTERNAL-0 "TwoThetaTheta"
*MEAS_COND_AXIS_NAME_INTERNAL-1 "Spin"
*MEAS_COND_AXIS_NAME_INTERNAL-2 "Change"
*MEAS_COND_AXIS_NAME_INTERNAL-3 "IncidentSollerSlit"
*MEAS_COND_AXIS_NAME_INTERNAL-4 "IncidentAxdSlit"
*MEAS_COND_AXIS_NAME_INTERNAL-5 "IncidentSlitBox"
*MEAS_COND_AXIS_NAME_INTERNAL-6 "ReceivingSlitBox1"
*MEAS_COND_AXIS_NAME_INTERNAL-7 "ReceivingSollerSlit"
*MEAS_COND_AXIS_NAME_INTERNAL-8 "ReceivingSlitBox2"
*MEAS_COND_AXIS_NAME_INTERNAL-9 "Filter"
*MEAS_COND_AXIS_NAME_INTERNAL-10 "CounterMonochromator"
*MEAS_COND_AXIS_NAME_INTERNAL-11 "PHA"
*MEAS_COND_AXIS_NAME_MAGICNO-0 "268632064.0000000000"
*MEAS_COND_AXIS_NAME_MAGICNO-1 "16842752.0000000000"
*MEAS_COND_AXIS_NAME_MAGICNO-2 "16842752.0000000000"
*MEAS_COND_AXIS_NAME_MAGICNO-3 "20971521.0000000000"
*MEAS_COND_AXIS_NAME_MAGICNO-4 "22020097.0000000000"
*MEAS_COND_AXIS_NAME_MAGICNO-5 "22020097.0000000000"
*MEAS_COND_AXIS_NAME_MAGICNO-6 "23068673.0000000000"
*MEAS_COND_AXIS_NAME_MAGICNO-7 "20971521.0000000000"
*MEAS_COND_AXIS_NAME_MAGICNO-8 "23068673.0000000000"
*MEAS_COND_AXIS_NAME_MAGICNO-9 "20971521.0000000000"
*MEAS_COND_AXIS_NAME_MAGICNO-10 "20971521.0000000000"
*MEAS_COND_AXIS_NAME_MAGICNO-11 "0.0000000000"
*MEAS_COND_AXIS_OFFSET-0 "0.0000000000"
*MEAS_COND_AXIS_OFFSET-1 "-"
*MEAS_COND_AXIS_OFFSET-2 "-"
*MEAS_COND_AXIS_OFFSET-3 "-"
*MEAS_COND_AXIS_OFFSET-4 "-"
*MEAS_COND_AXIS_OFFSET-5 "-"
*MEAS_COND_AXIS_OFFSET-6 "-"
*MEAS_COND_AXIS_OFFSET-7 "-"
*MEAS_COND_AXIS_OFFSET-8 "-"
*MEAS_COND_AXIS_OFFSET-9 "-"
*MEAS_COND_AXIS_OFFSET-10 "-"
*MEAS_COND_AXIS_OFFSET-11 "-"
*MEAS_COND_AXIS_POSITION-0 "92.4250000000"
*MEAS_COND_AXIS_POSITION-1 "0.0000000000"
*MEAS_COND_AXIS_POSITION-2 "4.0000000000"
*MEAS_COND_AXIS_POSITION-3 "2.5deg"
*MEAS_COND_AXIS_POSITION-4 "10.0mm"
*MEAS_COND_AXIS_POSITION-5 "0.625deg"
*MEAS_COND_AXIS_POSITION-6 "13.0mm"
*MEAS_COND_AXIS_POSITION-7 "2.5deg"
*MEAS_COND_AXIS_POSITION-8 "13.0mm"
*MEAS_COND_AXIS_POSITION-9 "K-beta(x2)"
*MEAS_COND_AXIS_POSITION-10 "None"
*MEAS_COND_AXIS_POSITION-11 "40.0000000000"
*MEAS_COND_AXIS_UNIT-0 "deg"
*MEAS_COND_AXIS_UNIT-1 ""
*MEAS_COND_AXIS_UNIT-2 ""
*MEAS_COND_AXIS_UNIT-3 ""
*MEAS_COND_AXIS_UNIT-4 ""
*MEAS_COND_AXIS_UNIT-5 ""
*MEAS_COND_AXIS_UNIT-6 ""
*MEAS_COND_AXIS_UNIT-7 ""
*MEAS_COND_AXIS_UNIT-8 ""
*MEAS_COND_AXIS_UNIT-9 ""
*MEAS_COND_AXIS_UNIT-10 ""
*MEAS_COND_AXIS_UNIT-11 "div"
*MEAS_COND_CORRECTION_SLIT_COUNTERMONO "None"
*MEAS_COND_CORRECTION_SLIT_DS "0.625deg"
*MEAS_COND_CORRECTION_SLIT_FILTER "None"
*MEAS_COND_CORRECTION_SLIT_IHS "10.0mm"
*MEAS_COND_CORRECTION_SLIT_RS "13.0mm"
*MEAS_COND_CORRECTION_SLIT_SOLLER_INC "2.5deg"
*MEAS_COND_CORRECTION_SLIT_SOLLER_REC "2.5deg"
*MEAS_COND_CORRECTION_SLIT_SS "13.0mm"
*MEAS_COND_COUNTER_CNTLOSS_CORR "0.0000000000"
*MEAS_COND_COUNTER_PHABASE "40.0000000000"
*MEAS_COND_COUNTER_PHAWINDOW "15.0000000000"
*MEAS_COND_COUNTER_PHA_UNIT "div"
*MEAS_COND_COUNTER_TAUDIFF "0.2500000000"
*MEAS_COND_COUNTER_TAUINT "0.7500000000"
*MEAS_COND_IRRADIATION_MODE "OFF"
*MEAS_COND_IRRADIATION_WIDTH ""
*MEAS_COND_OPT_ATTR " "
*MEAS_COND_OPT_NAME ""
*MEAS_COND_UNSYMMETRIC_MODE "OFF"
*MEAS_COND_XG_CURRENT "15.0000000000"
*MEAS_COND_XG_VOLTAGE "40.0000000000"
*MEAS_COND_XG_WAVE_TYPE "Ka"
*MEAS_DATA_COUNT "4251.0000000000"
*MEAS_SCAN_AXIS_X "Theta/2-Theta"
*MEAS_SCAN_AXIS_X_INTERNAL "TwoThetaTheta"
*MEAS_SCAN_END_TIME "03/03/17 15:55:16"
*MEAS_SCAN_MODE "CONTINUOUS"
*MEAS_SCAN_MONITOR "0"
*MEAS_SCAN_RESOLUTION_X "0.005"
*MEAS_SCAN_SPEED "5.000"
*MEAS_SCAN_SPEED_UNIT "deg/min"
*MEAS_SCAN_START "5.0000000000"
*MEAS_SCAN_START_TIME "03/03/17 15:36:50"
*MEAS_SCAN_STEP "0.0200000000"
*MEAS_SCAN_STOP "90.0000000000"
*MEAS_SCAN_UNIT_X "deg"
*MEAS_SCAN_UNIT_Y "counts"
*SLIT_SYSTEM "0"
*RAS_HEADER_END
*RAS_INT_START
5.000 1410.000 1.000
5.060 1319.000 1.000
5.120 1373.000 1.000
5.180 1321.000 1.000
5.240 1351.000 1.000
5.300 1332.000 1.000
5.360 1317.000 1.000
5.420 1292.000 1.000
5.480 1365.000 1.000
5.540 1357.000 1.000
5.600 1316.000 1.000
5.660 1298.000 1.000
5.720 1226.000 1.000
5.780 1278.000 1.000
5.840 1306.000 1.000
5.900 1309.000 1.000
5.960 1296.000 1.000
6.020 1247.000 1.000
6.080 1293.000 1.000
6.140 1284.000 1.000
6.200 1304.000 1.000
6.260 1346.000 1.000
6.320 1311.000 1.000
6.380 1320.000 1.000
6.440 1293.000 1.000
6.500 1253.000 1.000
6.560 1257.000 1.000
6.620 1281.000 1.000
6.680 1275.000 1.000
6.740 1283.000 1.000
6.800 1340.000 1.000
6.860 1333.000 1.000
6.920 1275.000 1.000
6.980 1263.000 1.000
7.040 1247.000 1.000
7.100 1323.000 1.000
7.160 1319.000 1.000
7.220 1277.000 1.000
7.280 1283.000 1.000
7.340 1288.000 1.000
7.400 1292.000 1.000
7.460 1287.000 1.000
7.520 1269.000 1.000
7.580 1272.000 1.000
7.640 1322.000 1.000
7.700 1340.000 1.000
7.760 1311.000 1.000
7.820 1316.000 1.000
7.880 1292.000 1.000
7.940 1312.000 1.000
8.000 1252.000 1.000
8.060 1261.000 1.000
8.120 1323.000 1.000
8.180 1338.000 1.000
8.240 1305.000 1.000
8.300 1326.000 1.000
8.360 1360.000 1.000
8.420 1277.000 1.000
8.480 1286.000 1.000
8.540 1318.000 1.000
8.600 1298.000 1.000
8.660 1285.000 1.000
8.720 1318.000 1.000
8.780 1267.000 1.000
8.840 1318.000 1.000
8.900 1295.000 1.000
8.960 1290.000 1.000
9.020 1355.000 1.000
9.080 1336.000 1.000
9.140 1370.000 1.000
9.200 1303.000 1.000
9.260 1319.000 1.000
9.320 1363.000 1.000
9.380 1349.000 1.000
9.440 1357.000 1.000
9.500 1272.000 1.000
9.560 1326.000 1.000
9.620 1355.000 1.000
9.680 1385.000 1.000
9.740 1318.000 1.000
9.800 1360.000 1.000
9.860 1369.000 1.000
9.920 1381.000 1.000
9.980 1370.000 1.000
10.040 1359.000 1.000
10.100 1381.000 1.000
10.160 1395.000 1.000
10.220 1378.000 1.000
10.280 1422.000 1.000
10.340 1425.000 1.000
10.400 1446.000 1.000
10.460 1373.000 1.000
10.520 1388.000 1.000
10.580 1451.000 1.000
10.640 1462.000 1.000
10.700 1409.000 1.000
10.760 1465.000 1.000
10.820 1427.000 1.000
10.880 1479.000 1.000
10.940 1471.000 1.000
11.000 1455.000 1.000
11.060 1471.000 1.000
11.120 1517.000 1.000
11.180 1510.000 1.000
11.240 1507.000 1.000
11.300 1500.000 1.000
11.360 1522.000 1.000
11.420 1564.000 1.000
11.480 1557.000 1.000
11.540 1477.000 1.000
11.600 1516.000 1.000
11.660 1503.000 1.000
11.720 1550.000 1.000
11.780 1566.000 1.000
11.840 1517.000 1.000
11.900 1553.000 1.000
11.960 1521.000 1.000
12.020 1533.000 1.000
12.080 1540.000 1.000
12.140 1629.000 1.000
12.200 1598.000 1.000
12.260 1612.000 1.000
12.320 1618.000 1.000
12.380 1577.000 1.000
12.440 1616.000 1.000
12.500 1649.000 1.000
12.560 1600.000 1.000
12.620 1517.000 1.000
12.680 1579.000 1.000
12.740 1611.000 1.000
12.800 1606.000 1.000
12.860 1618.000 1.000
12.920 1622.000 1.000
12.980 1638.000 1.000
13.040 1634.000 1.000
13.100 1681.000 1.000
13.160 1681.000 1.000
13.220 1674.000 1.000
13.280 1607.000 1.000
13.340 1671.000 1.000
13.400 1650.000 1.000
13.460 1682.000 1.000
13.520 1667.000 1.000
13.580 1671.000 1.000
13.640 1643.000 1.000
13.700 1668.000 1.000
13.760 1724.000 1.000
13.820 1665.000 1.000
13.880 1678.000 1.000
13.940 1684.000 1.000
14.000 1646.000 1.000
14.060 1692.000 1.000
14.120 1706.000 1.000
14.180 1727.000 1.000
14.240 1693.000 1.000
14.300 1705.000 1.000
14.360 1732.000 1.000
14.420 1697.000 1.000
14.480 1708.000 1.000
14.540 1739.000 1.000
14.600 1752.000 1.000
14.660 1706.000 1.000
14.720 1753.000 1.000
14.780 1735.000 1.000
14.840 1677.000 1.000
14.900 1707.000 1.000
14.960 1735.000 1.000
15.020 1726.000 1.000
15.080 1770.000 1.000
15.140 1788.000 1.000
15.200 1732.000 1.000
15.260 1750.000 1.000
15.320 1756.000 1.000
15.380 1791.000 1.000
15.440 1735.000 1.000
15.500 1749.000 1.000
15.560 1808.000 1.000
15.620 1789.000 1.000
15.680 1773.000 1.000
15.740 1787.000 1.000
15.800 1767.000 1.000
15.860 1818.000 1.000
15.920 1843.000 1.000
15.980 1799.000 1.000
16.040 1749.000 1.000
16.100 1788.000 1.000
16.160 1766.000 1.000
16.220 1822.000 1.000
16.280 1847.000 1.000
16.340 1810.000 1.000
16.400 1805.000 1.000
16.460 1803.000 1.000
16.520 1823.000 1.000
16.580 1797.000 1.000
16.640 1813.000 1.000
16.700 1816.000 1.000
16.760 1836.000 1.000
16.820 1828.000 1.000
16.880 1801.000 1.000
16.940 1786.000 1.000
17.000 1824.000 1.000
17.060 1854.000 1.000
17.120 1873.000 1.000
17.180 1897.000 1.000
17.240 1863.000 1.000
17.300 1833.000 1.000
17.360 1880.000 1.000
17.420 1935.000 1.000
17.480 1816.000 1.000
17.540 1926.000 1.000
17.600 1921.000 1.000
17.660 1863.000 1.000
17.720 1916.000 1.000
17.780 1847.000 1.000
17.840 1851.000 1.000
17.900 1898.000 1.000
17.960 1908.000 1.000
18.020 1893.000 1.000
18.080 2013.000 1.000
18.140 2041.000 1.000
18.200 1941.000 1.000
18.260 1935.000 1.000
18.320 1949.000 1.000
18.380 1926.000 1.000
18.440 1900.000 1.000
18.500 1890.000 1.000
18.560 1927.000 1.000
18.620 1932.000 1.000
18.680 1953.000 1.000
18.740 1898.000 1.000
18.800 1951.000 1.000
18.860 1900.000 1.000
18.920 1925.000 1.000
18.980 1989.000 1.000
19.040 1927.000 1.000
19.100 1950.000 1.000
19.160 1967.000 1.000
19.220 1937.000 1.000
19.280 2010.000 1.000
19.340 1970.000 1.000
19.400 1955.000 1.000
19.460 1996.000 1.000
19.520 1979.000 1.000
19.580 1940.000 1.000
19.640 1958.000 1.000
19.700 2013.000 1.000
19.760 1947.000 1.000
19.820 2047.000 1.000
19.880 2008.000 1.000
19.940 2003.000 1.000
20.000 1992.000 1.000
20.060 1976.000 1.000
20.120 1962.000 1.000
20.180 2032.000 1.000
20.240 1959.000 1.000
20.300 2038.000 1.000
20.360 2048.000 1.000
20.420 2031.000 1.000
20.480 2045.000 1.000
20.540 2020.000 1.000
20.600 1959.000 1.000
20.660 2006.000 1.000
20.720 2025.000 1.000
20.780 1981.000 1.000
20.840 1995.000 1.000
20.900 1993.000 1.000
20.960 2028.000 1.000
21.020 2055.000 1.000
21.080 1987.000 1.000
21.140 1970.000 1.000
21.200 2066.000 1.000
21.260 2010.000 1.000
21.320 2015.000 1.000
21.380 2028.000 1.000
21.440 2044.000 1.000
21.500 2072.000 1.000
21.560 2063.000 1.000
21.620 2034.000 1.000
21.680 2053.000 1.000
21.740 2050.000 1.000
21.800 2098.000 1.000
21.860 2108.000 1.000
21.920 2068.000 1.000
21.980 2044.000 1.000
22.040 1989.000 1.000
22.100 2098.000 1.000
22.160 2029.000 1.000
22.220 2007.000 1.000
22.280 2037.000 1.000
22.340 2049.000 1.000
22.400 2014.000 1.000
22.460 2030.000 1.000
22.520 2095.000 1.000
22.580 2021.000 1.000
22.640 2131.000 1.000
22.700 2121.000 1.000
22.760 2071.000 1.000
22.820 2025.000 1.000
22.880 2105.000 1.000
22.940 2075.000 1.000
23.000 2091.000 1.000
23.060 2108.000 1.000
23.120 2112.000 1.000
23.180 2104.000 1.000
23.240 2112.000 1.000
23.300 2118.000 1.000
23.360 2090.000 1.000
23.420 2129.000 1.000
23.480 2127.000 1.000
23.540 2042.000 1.000
23.600 2144.000 1.000
23.660 2172.000 1.000
23.720 2184.000 1.000
23.780 2180.000 1.000
23.840 2263.000 1.000
23.900 2333.000 1.000
23.960 2649.000 1.000
24.020 3124.000 1.000
24.080 3394.000 1.000
24.140 3004.000 1.000
24.200 2578.000 1.000
24.260 2318.000 1.000
24.320 2220.000 1.000
24.380 2219.000 1.000
24.440 2186.000 1.000
24.500 2166.000 1.000
24.560 2109.000 1.000
24.620 2147.000 1.000
24.680 2168.000 1.000
24.740 2152.000 1.000
24.800 2232.000 1.000
24.860 2132.000 1.000
24.920 2186.000 1.000
24.980 2129.000 1.000
25.040 2098.000 1.000
25.100 2129.000 1.000
25.160 2127.000 1.000
25.220 2119.000 1.000
25.280 2104.000 1.000
25.340 2124.000 1.000
25.400 2146.000 1.000
25.460 2131.000 1.000
25.520 2146.000 1.000
25.580 2211.000 1.000
25.640 2163.000 1.000
25.700 2169.000 1.000
25.760 2162.000 1.000
25.820 2132.000 1.000
25.880 2154.000 1.000
25.940 2190.000 1.000
26.000 2160.000 1.000
26.060 2184.000 1.000
26.120 2175.000 1.000
26.180 2176.000 1.000
26.240 2322.000 1.000
26.300 2176.000 1.000
26.360 2219.000 1.000
26.420 2180.000 1.000
26.480 2263.000 1.000
26.540 2196.000 1.000
26.600 2223.000 1.000
26.660 2132.000 1.000
26.720 2124.000 1.000
26.780 2164.000 1.000
26.840 2210.000 1.000
26.900 2186.000 1.000
26.960 2151.000 1.000
27.020 2193.000 1.000
27.080 2195.000 1.000
27.140 2131.000 1.000
27.200 2131.000 1.000
27.260 2159.000 1.000
27.320 2174.000 1.000
27.380 2169.000 1.000
27.440 2170.000 1.000
27.500 2178.000 1.000
27.560 2197.000 1.000
27.620 2174.000 1.000
27.680 2136.000 1.000
27.740 2190.000 1.000
27.800 2190.000 1.000
27.860 2187.000 1.000
27.920 2250.000 1.000
27.980 2187.000 1.000
28.040 2205.000 1.000
28.100 2195.000 1.000
28.160 2161.000 1.000
28.220 2222.000 1.000
28.280 2236.000 1.000
28.340 2160.000 1.000
28.400 2164.000 1.000
28.460 2185.000 1.000
28.520 2164.000 1.000
28.580 2181.000 1.000
28.640 2149.000 1.000
28.700 2214.000 1.000
28.760 2132.000 1.000
28.820 2192.000 1.000
28.880 2164.000 1.000
28.940 2138.000 1.000
29.000 2197.000 1.000
29.060 2190.000 1.000
29.120 2188.000 1.000
29.180 2189.000 1.000
29.240 2169.000 1.000
29.300 2222.000 1.000
29.360 2167.000 1.000
29.420 2159.000 1.000
29.480 2230.000 1.000
29.540 2132.000 1.000
29.600 2273.000 1.000
29.660 2257.000 1.000
29.720 2345.000 1.000
29.780 2440.000 1.000
29.840 2626.000 1.000
29.900 2452.000 1.000
29.960 2339.000 1.000
30.020 2253.000 1.000
30.080 2215.000 1.000
30.140 2202.000 1.000
30.200 2166.000 1.000
30.260 2227.000 1.000
30.320 2197.000 1.000
30.380 2224.000 1.000
30.440 2240.000 1.000
30.500 2219.000 1.000
30.560 2205.000 1.000
30.620 2206.000 1.000
30.680 2182.000 1.000
30.740 2175.000 1.000
30.800 2206.000 1.000
30.860 2164.000 1.000
30.920 2246.000 1.000
30.980 2208.000 1.000
31.040 2240.000 1.000
31.100 2212.000 1.000
31.160 2267.000 1.000
31.220 2222.000 1.000
31.280 2211.000 1.000
31.340 2220.000 1.000
31.400 2255.000 1.000
31.460 2281.000 1.000
31.520 2316.000 1.000
31.580 2659.000 1.000
31.640 4014.000 1.000
31.700 5452.000 1.000
31.760 4183.000 1.000
31.820 2555.000 1.000
31.880 2294.000 1.000
31.940 2250.000 1.000
32.000 2300.000 1.000
32.060 2262.000 1.000
32.120 2220.000 1.000
32.180 2270.000 1.000
32.240 2286.000 1.000
32.300 2260.000 1.000
32.360 2302.000 1.000
32.420 2307.000 1.000
32.480 2282.000 1.000
32.540 2300.000 1.000
32.600 2285.000 1.000
32.660 2365.000 1.000
32.720 2379.000 1.000
32.780 2478.000 1.000
32.840 2624.000 1.000
32.900 2999.000 1.000
32.960 3626.000 1.000
33.020 5000.000 1.000
33.080 6224.000 1.000
33.140 5373.000 1.000
33.200 4125.000 1.000
33.260 3248.000 1.000
33.320 2702.000 1.000
33.380 2504.000 1.000
33.440 2448.000 1.000
33.500 2318.000 1.000
33.560 2275.000 1.000
33.620 2326.000 1.000
33.680 2224.000 1.000
33.740 2294.000 1.000
33.800 2237.000 1.000
33.860 2259.000 1.000
33.920 2243.000 1.000
33.980 2247.000 1.000
34.040 2205.000 1.000
34.100 2293.000 1.000
34.160 2291.000 1.000
34.220 2322.000 1.000
34.280 2419.000 1.000
34.340 2493.000 1.000
34.400 2377.000 1.000
34.460 2331.000 1.000
34.520 2296.000 1.000
34.580 2326.000 1.000
34.640 2284.000 1.000
34.700 2305.000 1.000
34.760 2256.000 1.000
34.820 2245.000 1.000
34.880 2347.000 1.000
34.940 2293.000 1.000
35.000 2467.000 1.000
35.060 2588.000 1.000
35.120 3058.000 1.000
35.180 3279.000 1.000
35.240 3172.000 1.000
35.300 3016.000 1.000
35.360 3018.000 1.000
35.420 3308.000 1.000
35.480 4169.000 1.000
35.540 5251.000 1.000
35.600 4895.000 1.000
35.660 4195.000 1.000
35.720 3313.000 1.000
35.780 2823.000 1.000
35.840 2584.000 1.000
35.900 2415.000 1.000
35.960 2440.000 1.000
36.020 2332.000 1.000
36.080 2471.000 1.000
36.140 2891.000 1.000
36.200 2879.000 1.000
36.260 2685.000 1.000
36.320 2392.000 1.000
36.380 2260.000 1.000
36.440 2339.000 1.000
36.500 2226.000 1.000
36.560 2267.000 1.000
36.620 2242.000 1.000
36.680 2233.000 1.000
36.740 2235.000 1.000
36.800 2310.000 1.000
36.860 2247.000 1.000
36.920 2233.000 1.000
36.980 2243.000 1.000
37.040 2158.000 1.000
37.100 2201.000 1.000
37.160 2230.000 1.000
37.220 2258.000 1.000
37.280 2241.000 1.000
37.340 2226.000 1.000
37.400 2186.000 1.000
37.460 2230.000 1.000
37.520 2237.000 1.000
37.580 2177.000 1.000
37.640 2212.000 1.000
37.700 2260.000 1.000
37.760 2239.000 1.000
37.820 2272.000 1.000
37.880 2252.000 1.000
37.940 2265.000 1.000
38.000 2196.000 1.000
38.060 2292.000 1.000
38.120 2211.000 1.000
38.180 2259.000 1.000
38.240 2210.000 1.000
38.300 2216.000 1.000
38.360 2234.000 1.000
38.420 2217.000 1.000
38.480 2272.000 1.000
38.540 2219.000 1.000
38.600 2200.000 1.000
38.660 2180.000 1.000
38.720 2296.000 1.000
38.780 2227.000 1.000
38.840 2255.000 1.000
38.900 2223.000 1.000
38.960 2273.000 1.000
39.020 2266.000 1.000
39.080 2273.000 1.000
39.140 2317.000 1.000
39.200 2301.000 1.000
39.260 2284.000 1.000
39.320 2271.000 1.000
39.380 2157.000 1.000
39.440 2169.000 1.000
39.500 2231.000 1.000
39.560 2217.000 1.000
39.620 2220.000 1.000
39.680 2171.000 1.000
39.740 2246.000 1.000
39.800 2274.000 1.000
39.860 2309.000 1.000
39.920 2222.000 1.000
39.980 2234.000 1.000
40.040 2250.000 1.000
40.100 2209.000 1.000
40.160 2246.000 1.000
40.220 2202.000 1.000
40.280 2313.000 1.000
40.340 2258.000 1.000
40.400 2225.000 1.000
40.460 2308.000 1.000
40.520 2264.000 1.000
40.580 2421.000 1.000
40.640 2463.000 1.000
40.700 2614.000 1.000
40.760 2923.000 1.000
40.820 2980.000 1.000
40.880 2811.000 1.000
40.940 2575.000 1.000
41.000 2496.000 1.000
41.060 2377.000 1.000
41.120 2315.000 1.000
41.180 2265.000 1.000
41.240 2223.000 1.000
41.300 2286.000 1.000
41.360 2283.000 1.000
41.420 2283.000 1.000
41.480 2216.000 1.000
41.540 2272.000 1.000
41.600 2241.000 1.000
41.660 2225.000 1.000
41.720 2205.000 1.000
41.780 2206.000 1.000
41.840 2207.000 1.000
41.900 2261.000 1.000
41.960 2188.000 1.000
42.020 2186.000 1.000
42.080 2179.000 1.000
42.140 2231.000 1.000
42.200 2204.000 1.000
42.260 2218.000 1.000
42.320 2245.000 1.000
42.380 2242.000 1.000
42.440 2234.000 1.000
42.500 2213.000 1.000
42.560 2217.000 1.000
42.620 2247.000 1.000
42.680 2257.000 1.000
42.740 2293.000 1.000
42.800 2329.000 1.000
42.860 2333.000 1.000
42.920 2291.000 1.000
42.980 2248.000 1.000
43.040 2216.000 1.000
43.100 2225.000 1.000
43.160 2236.000 1.000
43.220 2218.000 1.000
43.280 2277.000 1.000
43.340 2241.000 1.000
43.400 2258.000 1.000
43.460 2267.000 1.000
43.520 2264.000 1.000
43.580 2289.000 1.000
43.640 2219.000 1.000
43.700 2195.000 1.000
43.760 2219.000 1.000
43.820 2223.000 1.000
43.880 2190.000 1.000
43.940 2222.000 1.000
44.000 2180.000 1.000
44.060 2220.000 1.000
44.120 2238.000 1.000
44.180 2226.000 1.000
44.240 2181.000 1.000
44.300 2245.000 1.000
44.360 2212.000 1.000
44.420 2176.000 1.000
44.480 2232.000 1.000
44.540 2179.000 1.000
44.600 2230.000 1.000
44.660 2191.000 1.000
44.720 2153.000 1.000
44.780 2223.000 1.000
44.840 2195.000 1.000
44.900 2157.000 1.000
44.960 2228.000 1.000
45.020 2161.000 1.000
45.080 2226.000 1.000
45.140 2221.000 1.000
45.200 2237.000 1.000
45.260 2268.000 1.000
45.320 2229.000 1.000
45.380 2205.000 1.000
45.440 2208.000 1.000
45.500 2210.000 1.000
45.560 2213.000 1.000
45.620 2144.000 1.000
45.680 2191.000 1.000
45.740 2229.000 1.000
45.800 2140.000 1.000
45.860 2178.000 1.000
45.920 2238.000 1.000
45.980 2189.000 1.000
46.040 2197.000 1.000
46.100 2156.000 1.000
46.160 2158.000 1.000
46.220 2256.000 1.000
46.280 2177.000 1.000
46.340 2244.000 1.000
46.400 2210.000 1.000
46.460 2162.000 1.000
46.520 2206.000 1.000
46.580 2216.000 1.000
46.640 2167.000 1.000
46.700 2203.000 1.000
46.760 2166.000 1.000
46.820 2177.000 1.000
46.880 2178.000 1.000
46.940 2197.000 1.000
47.000 2168.000 1.000
47.060 2227.000 1.000
47.120 2181.000 1.000
47.180 2173.000 1.000
47.240 2223.000 1.000
47.300 2204.000 1.000
47.360 2204.000 1.000
47.420 2347.000 1.000
47.480 2367.000 1.000
47.540 2254.000 1.000
47.600 2306.000 1.000
47.660 2219.000 1.000
47.720 2217.000 1.000
47.780 2245.000 1.000
47.840 2179.000 1.000
47.900 2241.000 1.000
47.960 2233.000 1.000
48.020 2245.000 1.000
48.080 2216.000 1.000
48.140 2139.000 1.000
48.200 2190.000 1.000
48.260 2249.000 1.000
48.320 2215.000 1.000
48.380 2216.000 1.000
48.440 2192.000 1.000
48.500 2270.000 1.000
48.560 2146.000 1.000
48.620 2242.000 1.000
48.680 2242.000 1.000
48.740 2248.000 1.000
48.800 2264.000 1.000
48.860 2266.000 1.000
48.920 2257.000 1.000
48.980 2256.000 1.000
49.040 2320.000 1.000
49.100 2296.000 1.000
49.160 2487.000 1.000
49.220 2503.000 1.000
49.280 2760.000 1.000
49.340 3104.000 1.000
49.400 3317.000 1.000
49.460 3164.000 1.000
49.520 3048.000 1.000
49.580 2716.000 1.000
49.640 2560.000 1.000
49.700 2408.000 1.000
49.760 2306.000 1.000
49.820 2397.000 1.000
49.880 2284.000 1.000
49.940 2228.000 1.000
50.000 2273.000 1.000
50.060 2189.000 1.000
50.120 2201.000 1.000
50.180 2208.000 1.000
50.240 2232.000 1.000
50.300 2235.000 1.000
50.360 2229.000 1.000
50.420 2175.000 1.000
50.480 2205.000 1.000
50.540 2181.000 1.000
50.600 2169.000 1.000
50.660 2180.000 1.000
50.720 2208.000 1.000
50.780 2196.000 1.000
50.840 2176.000 1.000
50.900 2208.000 1.000
50.960 2195.000 1.000
51.020 2226.000 1.000
51.080 2229.000 1.000
51.140 2195.000 1.000
51.200 2141.000 1.000
51.260 2233.000 1.000
51.320 2188.000 1.000
51.380 2154.000 1.000
51.440 2260.000 1.000
51.500 2190.000 1.000
51.560 2162.000 1.000
51.620 2220.000 1.000
51.680 2271.000 1.000
51.740 2241.000 1.000
51.800 2242.000 1.000
51.860 2233.000 1.000
51.920 2226.000 1.000
51.980 2195.000 1.000
52.040 2246.000 1.000
52.100 2196.000 1.000
52.160 2140.000 1.000
52.220 2223.000 1.000
52.280 2142.000 1.000
52.340 2225.000 1.000
52.400 2247.000 1.000
52.460 2197.000 1.000
52.520 2211.000 1.000
52.580 2229.000 1.000
52.640 2200.000 1.000
52.700 2230.000 1.000
52.760 2163.000 1.000
52.820 2228.000 1.000
52.880 2200.000 1.000
52.940 2245.000 1.000
53.000 2302.000 1.000
53.060 2321.000 1.000
53.120 2233.000 1.000
53.180 2270.000 1.000
53.240 2232.000 1.000
53.300 2197.000 1.000
53.360 2254.000 1.000
53.420 2258.000 1.000
53.480 2243.000 1.000
53.540 2292.000 1.000
53.600 2289.000 1.000
53.660 2378.000 1.000
53.720 2440.000 1.000
53.780 2525.000 1.000
53.840 2654.000 1.000
53.900 3027.000 1.000
53.960 3482.000 1.000
54.020 3399.000 1.000
54.080 3240.000 1.000
54.140 3122.000 1.000
54.200 2737.000 1.000
54.260 2562.000 1.000
54.320 2531.000 1.000
54.380 2329.000 1.000
54.440 2325.000 1.000
54.500 2320.000 1.000
54.560 2270.000 1.000
54.620 2205.000 1.000
54.680 2283.000 1.000
54.740 2288.000 1.000
54.800 2236.000 1.000
54.860 2210.000 1.000
54.920 2175.000 1.000
54.980 2163.000 1.000
55.040 2223.000 1.000
55.100 2268.000 1.000
55.160 2171.000 1.000
55.220 2185.000 1.000
55.280 2226.000 1.000
55.340 2195.000 1.000
55.400 2136.000 1.000
55.460 2224.000 1.000
55.520 2205.000 1.000
55.580 2228.000 1.000
55.640 2218.000 1.000
55.700 2232.000 1.000
55.760 2147.000 1.000
55.820 2236.000 1.000
55.880 2202.000 1.000
55.940 2204.000 1.000
56.000 2221.000 1.000
56.060 2234.000 1.000
56.120 2227.000 1.000
56.180 2175.000 1.000
56.240 2260.000 1.000
56.300 2258.000 1.000
56.360 2381.000 1.000
56.420 2581.000 1.000
56.480 2929.000 1.000
56.540 2947.000 1.000
56.600 2632.000 1.000
56.660 2729.000 1.000
56.720 2439.000 1.000
56.780 2343.000 1.000
56.840 2244.000 1.000
56.900 2260.000 1.000
56.960 2260.000 1.000
57.020 2255.000 1.000
57.080 2242.000 1.000
57.140 2310.000 1.000
57.200 2223.000 1.000
57.260 2283.000 1.000
57.320 2365.000 1.000
57.380 2348.000 1.000
57.440 2469.000 1.000
57.500 2464.000 1.000
57.560 2488.000 1.000
57.620 2429.000 1.000
57.680 2365.000 1.000
57.740 2307.000 1.000
57.800 2297.000 1.000
57.860 2263.000 1.000
57.920 2252.000 1.000
57.980 2203.000 1.000
58.040 2211.000 1.000
58.100 2210.000 1.000
58.160 2250.000 1.000
58.220 2221.000 1.000
58.280 2185.000 1.000
58.340 2255.000 1.000
58.400 2171.000 1.000
58.460 2186.000 1.000
58.520 2163.000 1.000
58.580 2207.000 1.000
58.640 2197.000 1.000
58.700 2163.000 1.000
58.760 2126.000 1.000
58.820 2216.000 1.000
58.880 2205.000 1.000
58.940 2232.000 1.000
59.000 2152.000 1.000
59.060 2201.000 1.000
59.120 2183.000 1.000
59.180 2182.000 1.000
59.240 2182.000 1.000
59.300 2231.000 1.000
59.360 2209.000 1.000
59.420 2228.000 1.000
59.480 2227.000 1.000
59.540 2197.000 1.000
59.600 2176.000 1.000
59.660 2142.000 1.000
59.720 2168.000 1.000
59.780 2194.000 1.000
59.840 2273.000 1.000
59.900 2174.000 1.000
59.960 2175.000 1.000
60.020 2226.000 1.000
60.080 2215.000 1.000
60.140 2191.000 1.000
60.200 2156.000 1.000
60.260 2153.000 1.000
60.320 2159.000 1.000
60.380 2178.000 1.000
60.440 2171.000 1.000
60.500 2193.000 1.000
60.560 2249.000 1.000
60.620 2211.000 1.000
60.680 2172.000 1.000
60.740 2176.000 1.000
60.800 2200.000 1.000
60.860 2265.000 1.000
60.920 2199.000 1.000
60.980 2224.000 1.000
61.040 2204.000 1.000
61.100 2191.000 1.000
61.160 2224.000 1.000
61.220 2246.000 1.000
61.280 2145.000 1.000
61.340 2179.000 1.000
61.400 2166.000 1.000
61.460 2143.000 1.000
61.520 2181.000 1.000
61.580 2250.000 1.000
61.640 2224.000 1.000
61.700 2257.000 1.000
61.760 2265.000 1.000
61.820 2318.000 1.000
61.880 2336.000 1.000
61.940 2383.000 1.000
62.000 2505.000 1.000
62.060 2560.000 1.000
62.120 2638.000 1.000
62.180 2707.000 1.000
62.240 2802.000 1.000
62.300 3066.000 1.000
62.360 3208.000 1.000
62.420 2910.000 1.000
62.480 2842.000 1.000
62.540 2743.000 1.000
62.600 2580.000 1.000
62.660 2541.000 1.000
62.720 2543.000 1.000
62.780 2532.000 1.000
62.840 2346.000 1.000
62.900 2358.000 1.000
62.960 2412.000 1.000
63.020 2275.000 1.000
63.080 2243.000 1.000
63.140 2302.000 1.000
63.200 2233.000 1.000
63.260 2270.000 1.000
63.320 2311.000 1.000
63.380 2277.000 1.000
63.440 2284.000 1.000
63.500 2262.000 1.000
63.560 2278.000 1.000
63.620 2331.000 1.000
63.680 2480.000 1.000
63.740 2470.000 1.000
63.800 2609.000 1.000
63.860 2856.000 1.000
63.920 3034.000 1.000
63.980 2956.000 1.000
64.040 2782.000 1.000
64.100 2819.000 1.000
64.160 2611.000 1.000
64.220 2493.000 1.000
64.280 2403.000 1.000
64.340 2298.000 1.000
64.400 2333.000 1.000
64.460 2284.000 1.000
64.520 2250.000 1.000
64.580 2221.000 1.000
64.640 2199.000 1.000
64.700 2183.000 1.000
64.760 2182.000 1.000
64.820 2212.000 1.000
64.880 2206.000 1.000
64.940 2214.000 1.000
65.000 2194.000 1.000
65.060 2261.000 1.000
65.120 2248.000 1.000
65.180 2220.000 1.000
65.240 2187.000 1.000
65.300 2276.000 1.000
65.360 2199.000 1.000
65.420 2194.000 1.000
65.480 2236.000 1.000
65.540 2208.000 1.000
65.600 2225.000 1.000
65.660 2272.000 1.000
65.720 2167.000 1.000
65.780 2267.000 1.000
65.840 2220.000 1.000
65.900 2205.000 1.000
65.960 2249.000 1.000
66.020 2212.000 1.000
66.080 2235.000 1.000
66.140 2237.000 1.000
66.200 2233.000 1.000
66.260 2426.000 1.000
66.320 2341.000 1.000
66.380 2233.000 1.000
66.440 2353.000 1.000
66.500 2254.000 1.000
66.560 2167.000 1.000
66.620 2208.000 1.000
66.680 2222.000 1.000
66.740 2227.000 1.000
66.800 2167.000 1.000
66.860 2213.000 1.000
66.920 2119.000 1.000
66.980 2218.000 1.000
67.040 2215.000 1.000
67.100 2217.000 1.000
67.160 2265.000 1.000
67.220 2230.000 1.000
67.280 2217.000 1.000
67.340 2193.000 1.000
67.400 2177.000 1.000
67.460 2228.000 1.000
67.520 2233.000 1.000
67.580 2182.000 1.000
67.640 2279.000 1.000
67.700 2216.000 1.000
67.760 2233.000 1.000
67.820 2276.000 1.000
67.880 2252.000 1.000
67.940 2200.000 1.000
68.000 2212.000 1.000
68.060 2225.000 1.000
68.120 2179.000 1.000
68.180 2188.000 1.000
68.240 2181.000 1.000
68.300 2196.000 1.000
68.360 2208.000 1.000
68.420 2192.000 1.000
68.480 2184.000 1.000
68.540 2222.000 1.000
68.600 2219.000 1.000
68.660 2187.000 1.000
68.720 2196.000 1.000
68.780 2194.000 1.000
68.840 2225.000 1.000
68.900 2219.000 1.000
68.960 2241.000 1.000
69.020 2327.000 1.000
69.080 2209.000 1.000
69.140 2243.000 1.000
69.200 2237.000 1.000
69.260 2172.000 1.000
69.320 2157.000 1.000
69.380 2258.000 1.000
69.440 2236.000 1.000
69.500 2266.000 1.000
69.560 2188.000 1.000
69.620 2220.000 1.000
69.680 2280.000 1.000
69.740 2236.000 1.000
69.800 2207.000 1.000
69.860 2198.000 1.000
69.920 2191.000 1.000
69.980 2245.000 1.000
70.040 2165.000 1.000
70.100 2233.000 1.000
70.160 2143.000 1.000
70.220 2163.000 1.000
70.280 2214.000 1.000
70.340 2179.000 1.000
70.400 2158.000 1.000
70.460 2200.000 1.000
70.520 2216.000 1.000
70.580 2148.000 1.000
70.640 2252.000 1.000
70.700 2166.000 1.000
70.760 2191.000 1.000
70.820 2173.000 1.000
70.880 2190.000 1.000
70.940 2210.000 1.000
71.000 2192.000 1.000
71.060 2196.000 1.000
71.120 2160.000 1.000
71.180 2240.000 1.000
71.240 2181.000 1.000
71.300 2243.000 1.000
71.360 2236.000 1.000
71.420 2165.000 1.000
71.480 2175.000 1.000
71.540 2206.000 1.000
71.600 2193.000 1.000
71.660 2300.000 1.000
71.720 2334.000 1.000
71.780 2348.000 1.000
71.840 2474.000 1.000
71.900 2385.000 1.000
71.960 2354.000 1.000
72.020 2317.000 1.000
72.080 2439.000 1.000
72.140 2308.000 1.000
72.200 2311.000 1.000
72.260 2298.000 1.000
72.320 2228.000 1.000
72.380 2252.000 1.000
72.440 2249.000 1.000
72.500 2247.000 1.000
72.560 2211.000 1.000
72.620 2217.000 1.000
72.680 2246.000 1.000
72.740 2242.000 1.000
72.800 2219.000 1.000
72.860 2232.000 1.000
72.920 2201.000 1.000
72.980 2215.000 1.000
73.040 2162.000 1.000
73.100 2238.000 1.000
73.160 2277.000 1.000
73.220 2167.000 1.000
73.280 2195.000 1.000
73.340 2263.000 1.000
73.400 2225.000 1.000
73.460 2312.000 1.000
73.520 2230.000 1.000
73.580 2232.000 1.000
73.640 2276.000 1.000
73.700 2211.000 1.000
73.760 2170.000 1.000
73.820 2198.000 1.000
73.880 2197.000 1.000
73.940 2165.000 1.000
74.000 2209.000 1.000
74.060 2157.000 1.000
74.120 2151.000 1.000
74.180 2167.000 1.000
74.240 2187.000 1.000
74.300 2175.000 1.000
74.360 2150.000 1.000
74.420 2134.000 1.000
74.480 2255.000 1.000
74.540 2191.000 1.000
74.600 2250.000 1.000
74.660 2223.000 1.000
74.720 2259.000 1.000
74.780 2176.000 1.000
74.840 2203.000 1.000
74.900 2250.000 1.000
74.960 2222.000 1.000
75.020 2250.000 1.000
75.080 2161.000 1.000
75.140 2339.000 1.000
75.200 2375.000 1.000
75.260 2297.000 1.000
75.320 2361.000 1.000
75.380 2379.000 1.000
75.440 2307.000 1.000
75.500 2321.000 1.000
75.560 2255.000 1.000
75.620 2245.000 1.000
75.680 2306.000 1.000
75.740 2222.000 1.000
75.800 2183.000 1.000
75.860 2197.000 1.000
75.920 2243.000 1.000
75.980 2233.000 1.000
76.040 2178.000 1.000
76.100 2178.000 1.000
76.160 2152.000 1.000
76.220 2196.000 1.000
76.280 2181.000 1.000
76.340 2130.000 1.000
76.400 2176.000 1.000
76.460 2143.000 1.000
76.520 2159.000 1.000
76.580 2099.000 1.000
76.640 2199.000 1.000
76.700 2188.000 1.000
76.760 2224.000 1.000
76.820 2272.000 1.000
76.880 2207.000 1.000
76.940 2283.000 1.000
77.000 2187.000 1.000
77.060 2231.000 1.000
77.120 2248.000 1.000
77.180 2191.000 1.000
77.240 2197.000 1.000
77.300 2184.000 1.000
77.360 2229.000 1.000
77.420 2140.000 1.000
77.480 2142.000 1.000
77.540 2305.000 1.000
77.600 2283.000 1.000
77.660 2192.000 1.000
77.720 2270.000 1.000
77.780 2186.000 1.000
77.840 2261.000 1.000
77.900 2207.000 1.000
77.960 2189.000 1.000
78.020 2174.000 1.000
78.080 2135.000 1.000
78.140 2170.000 1.000
78.200 2202.000 1.000
78.260 2279.000 1.000
78.320 2180.000 1.000
78.380 2173.000 1.000
78.440 2221.000 1.000
78.500 2196.000 1.000
78.560 2210.000 1.000
78.620 2227.000 1.000
78.680 2189.000 1.000
78.740 2178.000 1.000
78.800 2227.000 1.000
78.860 2167.000 1.000
78.920 2185.000 1.000
78.980 2183.000 1.000
79.040 2195.000 1.000
79.100 2151.000 1.000
79.160 2203.000 1.000
79.220 2168.000 1.000
79.280 2214.000 1.000
79.340 2151.000 1.000
79.400 2233.000 1.000
79.460 2228.000 1.000
79.520 2202.000 1.000
79.580 2228.000 1.000
79.640 2130.000 1.000
79.700 2200.000 1.000
79.760 2187.000 1.000
79.820 2236.000 1.000
79.880 2177.000 1.000
79.940 2251.000 1.000
80.000 2226.000 1.000
80.060 2247.000 1.000
80.120 2155.000 1.000
80.180 2190.000 1.000
80.240 2341.000 1.000
80.300 2264.000 1.000
80.360 2258.000 1.000
80.420 2216.000 1.000
80.480 2340.000 1.000
80.540 2275.000 1.000
80.600 2307.000 1.000
80.660 2315.000 1.000
80.720 2252.000 1.000
80.780 2241.000 1.000
80.840 2331.000 1.000
80.900 2322.000 1.000
80.960 2195.000 1.000
81.020 2198.000 1.000
81.080 2199.000 1.000
81.140 2210.000 1.000
81.200 2147.000 1.000
81.260 2200.000 1.000
81.320 2255.000 1.000
81.380 2179.000 1.000
81.440 2158.000 1.000
81.500 2085.000 1.000
81.560 2273.000 1.000
81.620 2145.000 1.000
81.680 2146.000 1.000
81.740 2147.000 1.000
81.800 2202.000 1.000
81.860 2155.000 1.000
81.920 2172.000 1.000
81.980 2187.000 1.000
82.040 2248.000 1.000
82.100 2197.000 1.000
82.160 2207.000 1.000
82.220 2151.000 1.000
82.280 2180.000 1.000
82.340 2156.000 1.000
82.400 2212.000 1.000
82.460 2320.000 1.000
82.520 2206.000 1.000
82.580 2210.000 1.000
82.640 2240.000 1.000
82.700 2241.000 1.000
82.760 2286.000 1.000
82.820 2252.000 1.000
82.880 2299.000 1.000
82.940 2277.000 1.000
83.000 2270.000 1.000
83.060 2244.000 1.000
83.120 2255.000 1.000
83.180 2234.000 1.000
83.240 2197.000 1.000
83.300 2170.000 1.000
83.360 2267.000 1.000
83.420 2199.000 1.000
83.480 2192.000 1.000
83.540 2234.000 1.000
83.600 2192.000 1.000
83.660 2189.000 1.000
83.720 2198.000 1.000
83.780 2150.000 1.000
83.840 2137.000 1.000
83.900 2132.000 1.000
83.960 2226.000 1.000
84.020 2219.000 1.000
84.080 2194.000 1.000
84.140 2190.000 1.000
84.200 2189.000 1.000
84.260 2175.000 1.000
84.320 2160.000 1.000
84.380 2158.000 1.000
84.440 2248.000 1.000
84.500 2211.000 1.000
84.560 2172.000 1.000
84.620 2240.000 1.000
84.680 2188.000 1.000
84.740 2340.000 1.000
84.800 2320.000 1.000
84.860 2329.000 1.000
84.920 2319.000 1.000
84.980 2355.000 1.000
85.040 2303.000 1.000
85.100 2384.000 1.000
85.160 2277.000 1.000
85.220 2245.000 1.000
85.280 2242.000 1.000
85.340 2200.000 1.000
85.400 2263.000 1.000
85.460 2256.000 1.000
85.520 2300.000 1.000
85.580 2173.000 1.000
85.640 2207.000 1.000
85.700 2255.000 1.000
85.760 2240.000 1.000
85.820 2082.000 1.000
85.880 2178.000 1.000
85.940 2180.000 1.000
86.000 2202.000 1.000
86.060 2253.000 1.000
86.120 2201.000 1.000
86.180 2225.000 1.000
86.240 2215.000 1.000
86.300 2126.000 1.000
86.360 2213.000 1.000
86.420 2231.000 1.000
86.480 2298.000 1.000
86.540 2191.000 1.000
86.600 2244.000 1.000
86.660 2088.000 1.000
86.720 2127.000 1.000
86.780 2184.000 1.000
86.840 2253.000 1.000
86.900 2264.000 1.000
86.960 2145.000 1.000
87.020 2128.000 1.000
87.080 2173.000 1.000
87.140 2062.000 1.000
87.200 2222.000 1.000
87.260 2183.000 1.000
87.320 2184.000 1.000
87.380 2194.000 1.000
87.440 2175.000 1.000
87.500 2153.000 1.000
87.560 2148.000 1.000
87.620 2234.000 1.000
87.680 2150.000 1.000
87.740 2199.000 1.000
87.800 2226.000 1.000
87.860 2245.000 1.000
87.920 2154.000 1.000
87.980 2239.000 1.000
88.040 2262.000 1.000
88.100 2184.000 1.000
88.160 2216.000 1.000
88.220 2251.000 1.000
88.280 2197.000 1.000
88.340 2274.000 1.000
88.400 2328.000 1.000
88.460 2359.000 1.000
88.520 2320.000 1.000
88.580 2273.000 1.000
88.640 2320.000 1.000
88.700 2307.000 1.000
88.760 2269.000 1.000
88.820 2336.000 1.000
88.880 2275.000 1.000
88.940 2298.000 1.000
89.000 2210.000 1.000
89.060 2261.000 1.000
89.120 2275.000 1.000
89.180 2216.000 1.000
89.240 2291.000 1.000
89.300 2096.000 1.000
89.360 2204.000 1.000
89.420 2207.000 1.000
89.480 2274.000 1.000
89.540 2225.000 1.000
89.600 2191.000 1.000
89.660 2297.000 1.000
89.720 2193.000 1.000
89.780 2231.000 1.000
89.840 2274.000 1.000
89.900 2206.000 1.000
89.960 2156.000 1.000
90.000 2156.000 1.000
*RAS_INT_END
*RAS_DATA_END