File: xrd/ZnOCuCl2.ras
*RAS_DATA_START
*RAS_HEADER_START
*CORR_POS_DB_NAME "C_DteX_ASC-6_15122015"
*CORR_POS_GONIO_RADIUS ""
*CORR_POS_NODE_INDEX01 ""
*CORR_POS_NODE_INDEX02 ""
*CORR_POS_NODE_INDEX03 ""
*CORR_POS_NODE_INDEX04 ""
*CORR_POS_NODE_INDEX05 ""
*CORR_POS_NODE_INDEX06 ""
*CORR_POS_NODE_INDEX07 ""
*CORR_POS_NODE_INDEX08 ""
*CORR_POS_NODE_INDEX09 ""
*CORR_POS_NODE_INDEX10 ""
*CORR_POS_NODE_INDEX11 ""
*CORR_POS_NODE_LABEL01 "Si(111)"
*CORR_POS_NODE_LABEL02 "Si(220)"
*CORR_POS_NODE_LABEL03 "Si(311)"
*CORR_POS_NODE_LABEL04 "Si(400)"
*CORR_POS_NODE_LABEL05 "Si(331)"
*CORR_POS_NODE_LABEL06 "Si(422)"
*CORR_POS_NODE_LABEL07 "Si(511)"
*CORR_POS_NODE_LABEL08 "Si(440)"
*CORR_POS_NODE_LABEL09 "Si(531)"
*CORR_POS_NODE_LABEL10 "Si(620)"
*CORR_POS_NODE_LABEL11 "Si(533)"
*CORR_POS_NODE_POS_CALC01 "28.4137"
*CORR_POS_NODE_POS_CALC02 "47.2707"
*CORR_POS_NODE_POS_CALC03 "56.0883"
*CORR_POS_NODE_POS_CALC04 "69.0934"
*CORR_POS_NODE_POS_CALC05 "76.3385"
*CORR_POS_NODE_POS_CALC06 "87.9915"
*CORR_POS_NODE_POS_CALC07 "94.9137"
*CORR_POS_NODE_POS_CALC08 "106.67"
*CORR_POS_NODE_POS_CALC09 "114.054"
*CORR_POS_NODE_POS_CALC10 "127.508"
*CORR_POS_NODE_POS_CALC11 "136.858"
*CORR_POS_NODE_POS_MEAS01 "28.4844"
*CORR_POS_NODE_POS_MEAS02 "47.3386"
*CORR_POS_NODE_POS_MEAS03 "56.1592"
*CORR_POS_NODE_POS_MEAS04 "69.1708"
*CORR_POS_NODE_POS_MEAS05 "76.4167"
*CORR_POS_NODE_POS_MEAS06 "88.0714"
*CORR_POS_NODE_POS_MEAS07 "94.9948"
*CORR_POS_NODE_POS_MEAS08 "106.756"
*CORR_POS_NODE_POS_MEAS09 "114.134"
*CORR_POS_NODE_POS_MEAS10 "127.59"
*CORR_POS_NODE_POS_MEAS11 "136.946"
*CORR_POS_OPT_ATTR "集中法"
*CORR_POS_PARAM_MU ""
*CORR_POS_PARAM_PL ""
*CORR_POS_SEMODEL_TYPE "0"
*CORR_POS_STANDARD_TYPE ""
*CORR_POS_VALUE_ANALYZER "None"
*CORR_POS_VALUE_CMONO "None"
*CORR_POS_VALUE_IMONO "None"
*CORR_POS_VALUE_IS "0.625deg"
*CORR_POS_VALUE_ISL "10.0mm"
*CORR_POS_VALUE_ISOLLER "2.5deg"
*CORR_POS_VALUE_RS1 "13.0mm"
*CORR_POS_VALUE_RS2 "13.0mm"
*CORR_POS_VALUE_RSOLLER "2.5deg"
*CORR_POS_XG_FOCUS_L ""
*CORR_POS_XG_WAVE_TYPE ""
*CORR_POS_XG_WAVE_VALUE ""
*DISP_FMT_X "%.2f"
*DISP_FMT_Y "%.0f"
*DISP_FULLSCALE "41535.0000000000"
*DISP_LINE_COLOR "255.0000000000"
*DISP_LINE_STYLE "0.0000000000"
*DISP_LINE_WIDTH "0.2500000000"
*DISP_NOTE "Collected Data-1"
*DISP_OFFSET_Y "0.0000000000"
*DISP_PEAKSEARCH_UNIT_Y "cps"
*DISP_RANGE_BOTTOM "0.0000000000"
*DISP_RANGE_LEFT "5.0000000000"
*DISP_RANGE_LOGCUTOFF "0.0100000000"
*DISP_RANGE_RIGHT "90.0000000000"
*DISP_RANGE_TOP "41535.0000000000"
*DISP_SCALE_MODE_Y "0.0000000000"
*DISP_TAB_NAME "Theta/2-Theta"
*DISP_TITLE_Y "Intensity"
*DISP_UNIT_Y "cps"
*DISP_WINDOW_NAME "MSG_MACROENGINE"
*FILE_COMMENT " "
*FILE_MD5 ""
*FILE_MEMO " "
*FILE_OPERATOR "RIGAKU"
*FILE_SAMPLE "ZnOCuCl2"
*FILE_TYPE "RAS_RAW"
*FILE_USERGROUP "System Manager"
*FILE_VERSION "1.0000000000"
*HW_ATTACHMENT_ID "ATT1031"
*HW_ATTACHMENT_NAME "6サンプルチェンジャ|ASC-6"
*HW_COUNTER_ID-0 "CUT0025"
*HW_COUNTER_ID-1 "CUT0020"
*HW_COUNTER_ID-2 "CUT0020"
*HW_COUNTER_ID-3 "CMC0021"
*HW_COUNTER_NAME-0 "D/teX Ultra|D/teX Ultra"
*HW_COUNTER_NAME-1 "None|None"
*HW_COUNTER_NAME-2 "None|None"
*HW_COUNTER_NAME-3 "検出器モノクロメータ|Detector monochromator"
*HW_COUNTER_SELECT_NAME "D/teX Ultra|D/teX Ultra"
*HW_GONIOMETER_ID "GON0070"
*HW_GONIOMETER_NAME "MiniFlex 300/600|MiniFlex 300/600"
*HW_GONIOMETER_RADIUS-0 "79.0"
*HW_GONIOMETER_RADIUS-1 "91.5"
*HW_GONIOMETER_RADIUS-2 "150.0"
*HW_GONIOMETER_RADIUS-3 "0"
*HW_GONIOMETER_RADIUS-4 "103.4"
*HW_GONIOMETER_RADIUS-5 "150.0"
*HW_GONIOMETER_RADIUS-6 "46.6"
*HW_GONIOMETER_RADIUS-7 "160.0"
*HW_I_OPT_ID-0 "ISL0021"
*HW_I_OPT_ID-1 "ISO0021"
*HW_I_OPT_NAME-0 "発散スリット|Divergence slit"
*HW_I_OPT_NAME-1 "入射平行スリット|Incident parallel slit"
*HW_R_ATTENUATER_AUTOMODE "0"
*HW_R_OPT_ID-0 "RSS0021"
*HW_R_OPT_ID-1 "RSO0021"
*HW_R_OPT_ID-2 "RRS0021"
*HW_R_OPT_NAME-0 "散乱スリット|Scattering slit"
*HW_R_OPT_NAME-1 "受光平行スリット|Receiving soller slit"
*HW_R_OPT_NAME-2 "受光スリット|Receiving slit"
*HW_SAMPLE_HOLDER_ID "SMP0000"
*HW_SAMPLE_HOLDER_NAME "無し|None"
*HW_XG_CURRENT_MAX "15"
*HW_XG_CURRENT_MIN "2"
*HW_XG_CURRENT_RESOLUTION "1"
*HW_XG_CURRENT_UNIT "mA"
*HW_XG_FOCUS "1mm x 10mm"
*HW_XG_FOCUS_TYPE "Normal"
*HW_XG_ID ""
*HW_XG_NAME "300W/600W 封入管-B|300W/600W Sealed tube-B"
*HW_XG_TARGET_ATOMIC_NUMBER "29.0000000000"
*HW_XG_TARGET_NAME "Cu"
*HW_XG_TYPE "Hermetic"
*HW_XG_VOLTAGE_MAX "40"
*HW_XG_VOLTAGE_MIN "20"
*HW_XG_VOLTAGE_RESOLUTION "1"
*HW_XG_VOLTAGE_UNIT "kV"
*HW_XG_WATT_MAX "0.600"
*HW_XG_WATT_UNIT "kW"
*HW_XG_WAVE_LENGTH_ALPHA1 "1.540593"
*HW_XG_WAVE_LENGTH_ALPHA2 "1.544414"
*HW_XG_WAVE_LENGTH_BETA "1.392250"
*MEAS_COND_AXIS_NAME-0 "Theta/2-Theta"
*MEAS_COND_AXIS_NAME-1 "Spin"
*MEAS_COND_AXIS_NAME-2 "Change"
*MEAS_COND_AXIS_NAME-3 "Soller(inc.)"
*MEAS_COND_AXIS_NAME-4 "IHS"
*MEAS_COND_AXIS_NAME-5 "DS"
*MEAS_COND_AXIS_NAME-6 "SS"
*MEAS_COND_AXIS_NAME-7 "Soller(rec.)"
*MEAS_COND_AXIS_NAME-8 "RS"
*MEAS_COND_AXIS_NAME-9 "Filter"
*MEAS_COND_AXIS_NAME-10 "Monochromator"
*MEAS_COND_AXIS_NAME-11 "PHA"
*MEAS_COND_AXIS_NAME_INTERNAL-0 "TwoThetaTheta"
*MEAS_COND_AXIS_NAME_INTERNAL-1 "Spin"
*MEAS_COND_AXIS_NAME_INTERNAL-2 "Change"
*MEAS_COND_AXIS_NAME_INTERNAL-3 "IncidentSollerSlit"
*MEAS_COND_AXIS_NAME_INTERNAL-4 "IncidentAxdSlit"
*MEAS_COND_AXIS_NAME_INTERNAL-5 "IncidentSlitBox"
*MEAS_COND_AXIS_NAME_INTERNAL-6 "ReceivingSlitBox1"
*MEAS_COND_AXIS_NAME_INTERNAL-7 "ReceivingSollerSlit"
*MEAS_COND_AXIS_NAME_INTERNAL-8 "ReceivingSlitBox2"
*MEAS_COND_AXIS_NAME_INTERNAL-9 "Filter"
*MEAS_COND_AXIS_NAME_INTERNAL-10 "CounterMonochromator"
*MEAS_COND_AXIS_NAME_INTERNAL-11 "PHA"
*MEAS_COND_AXIS_NAME_MAGICNO-0 "268632064.0000000000"
*MEAS_COND_AXIS_NAME_MAGICNO-1 "16842752.0000000000"
*MEAS_COND_AXIS_NAME_MAGICNO-2 "16842752.0000000000"
*MEAS_COND_AXIS_NAME_MAGICNO-3 "20971521.0000000000"
*MEAS_COND_AXIS_NAME_MAGICNO-4 "22020097.0000000000"
*MEAS_COND_AXIS_NAME_MAGICNO-5 "22020097.0000000000"
*MEAS_COND_AXIS_NAME_MAGICNO-6 "23068673.0000000000"
*MEAS_COND_AXIS_NAME_MAGICNO-7 "20971521.0000000000"
*MEAS_COND_AXIS_NAME_MAGICNO-8 "23068673.0000000000"
*MEAS_COND_AXIS_NAME_MAGICNO-9 "20971521.0000000000"
*MEAS_COND_AXIS_NAME_MAGICNO-10 "20971521.0000000000"
*MEAS_COND_AXIS_NAME_MAGICNO-11 "0.0000000000"
*MEAS_COND_AXIS_OFFSET-0 "0.0000000000"
*MEAS_COND_AXIS_OFFSET-1 "-"
*MEAS_COND_AXIS_OFFSET-2 "-"
*MEAS_COND_AXIS_OFFSET-3 "-"
*MEAS_COND_AXIS_OFFSET-4 "-"
*MEAS_COND_AXIS_OFFSET-5 "-"
*MEAS_COND_AXIS_OFFSET-6 "-"
*MEAS_COND_AXIS_OFFSET-7 "-"
*MEAS_COND_AXIS_OFFSET-8 "-"
*MEAS_COND_AXIS_OFFSET-9 "-"
*MEAS_COND_AXIS_OFFSET-10 "-"
*MEAS_COND_AXIS_OFFSET-11 "-"
*MEAS_COND_AXIS_POSITION-0 "10.0000000000"
*MEAS_COND_AXIS_POSITION-1 "0.0000000000"
*MEAS_COND_AXIS_POSITION-2 "2.0000000000"
*MEAS_COND_AXIS_POSITION-3 "2.5deg"
*MEAS_COND_AXIS_POSITION-4 "10.0mm"
*MEAS_COND_AXIS_POSITION-5 "0.625deg"
*MEAS_COND_AXIS_POSITION-6 "13.0mm"
*MEAS_COND_AXIS_POSITION-7 "2.5deg"
*MEAS_COND_AXIS_POSITION-8 "13.0mm"
*MEAS_COND_AXIS_POSITION-9 "K-beta(x2)"
*MEAS_COND_AXIS_POSITION-10 "None"
*MEAS_COND_AXIS_POSITION-11 "40.0000000000"
*MEAS_COND_AXIS_UNIT-0 "deg"
*MEAS_COND_AXIS_UNIT-1 ""
*MEAS_COND_AXIS_UNIT-2 ""
*MEAS_COND_AXIS_UNIT-3 ""
*MEAS_COND_AXIS_UNIT-4 ""
*MEAS_COND_AXIS_UNIT-5 ""
*MEAS_COND_AXIS_UNIT-6 ""
*MEAS_COND_AXIS_UNIT-7 ""
*MEAS_COND_AXIS_UNIT-8 ""
*MEAS_COND_AXIS_UNIT-9 ""
*MEAS_COND_AXIS_UNIT-10 ""
*MEAS_COND_AXIS_UNIT-11 "div"
*MEAS_COND_CORRECTION_SLIT_COUNTERMONO "None"
*MEAS_COND_CORRECTION_SLIT_DS "0.625deg"
*MEAS_COND_CORRECTION_SLIT_FILTER "None"
*MEAS_COND_CORRECTION_SLIT_IHS "10.0mm"
*MEAS_COND_CORRECTION_SLIT_RS "13.0mm"
*MEAS_COND_CORRECTION_SLIT_SOLLER_INC "2.5deg"
*MEAS_COND_CORRECTION_SLIT_SOLLER_REC "2.5deg"
*MEAS_COND_CORRECTION_SLIT_SS "13.0mm"
*MEAS_COND_COUNTER_CNTLOSS_CORR "0.0000000000"
*MEAS_COND_COUNTER_PHABASE "40.0000000000"
*MEAS_COND_COUNTER_PHAWINDOW "15.0000000000"
*MEAS_COND_COUNTER_PHA_UNIT "div"
*MEAS_COND_COUNTER_TAUDIFF "0.2500000000"
*MEAS_COND_COUNTER_TAUINT "0.7500000000"
*MEAS_COND_IRRADIATION_MODE "OFF"
*MEAS_COND_IRRADIATION_WIDTH ""
*MEAS_COND_OPT_ATTR " "
*MEAS_COND_OPT_NAME ""
*MEAS_COND_UNSYMMETRIC_MODE "OFF"
*MEAS_COND_XG_CURRENT "15.0000000000"
*MEAS_COND_XG_VOLTAGE "40.0000000000"
*MEAS_COND_XG_WAVE_TYPE "Ka"
*MEAS_DATA_COUNT "4251.0000000000"
*MEAS_SCAN_AXIS_X "Theta/2-Theta"
*MEAS_SCAN_AXIS_X_INTERNAL "TwoThetaTheta"
*MEAS_SCAN_END_TIME "03/03/17 15:18:00"
*MEAS_SCAN_MODE "CONTINUOUS"
*MEAS_SCAN_MONITOR "0"
*MEAS_SCAN_RESOLUTION_X "0.005"
*MEAS_SCAN_SPEED "5.000"
*MEAS_SCAN_SPEED_UNIT "deg/min"
*MEAS_SCAN_START "5.0000000000"
*MEAS_SCAN_START_TIME "03/03/17 14:59:44"
*MEAS_SCAN_STEP "0.0200000000"
*MEAS_SCAN_STOP "90.0000000000"
*MEAS_SCAN_UNIT_X "deg"
*MEAS_SCAN_UNIT_Y "counts"
*SLIT_SYSTEM "0"
*RAS_HEADER_END
*RAS_INT_START
5.000 633.000 1.000
5.060 638.000 1.000
5.120 600.000 1.000
5.180 600.000 1.000
5.240 641.000 1.000
5.300 590.000 1.000
5.360 636.000 1.000
5.420 636.000 1.000
5.480 612.000 1.000
5.540 619.000 1.000
5.600 552.000 1.000
5.660 599.000 1.000
5.720 586.000 1.000
5.780 583.000 1.000
5.840 584.000 1.000
5.900 552.000 1.000
5.960 594.000 1.000
6.020 603.000 1.000
6.080 585.000 1.000
6.140 578.000 1.000
6.200 545.000 1.000
6.260 546.000 1.000
6.320 572.000 1.000
6.380 546.000 1.000
6.440 573.000 1.000
6.500 565.000 1.000
6.560 578.000 1.000
6.620 569.000 1.000
6.680 535.000 1.000
6.740 567.000 1.000
6.800 545.000 1.000
6.860 568.000 1.000
6.920 580.000 1.000
6.980 554.000 1.000
7.040 539.000 1.000
7.100 583.000 1.000
7.160 549.000 1.000
7.220 559.000 1.000
7.280 540.000 1.000
7.340 564.000 1.000
7.400 525.000 1.000
7.460 553.000 1.000
7.520 571.000 1.000
7.580 551.000 1.000
7.640 534.000 1.000
7.700 539.000 1.000
7.760 526.000 1.000
7.820 548.000 1.000
7.880 544.000 1.000
7.940 568.000 1.000
8.000 534.000 1.000
8.060 528.000 1.000
8.120 520.000 1.000
8.180 549.000 1.000
8.240 545.000 1.000
8.300 540.000 1.000
8.360 531.000 1.000
8.420 554.000 1.000
8.480 571.000 1.000
8.540 561.000 1.000
8.600 549.000 1.000
8.660 549.000 1.000
8.720 552.000 1.000
8.780 558.000 1.000
8.840 563.000 1.000
8.900 529.000 1.000
8.960 576.000 1.000
9.020 585.000 1.000
9.080 541.000 1.000
9.140 564.000 1.000
9.200 556.000 1.000
9.260 557.000 1.000
9.320 539.000 1.000
9.380 547.000 1.000
9.440 562.000 1.000
9.500 532.000 1.000
9.560 572.000 1.000
9.620 573.000 1.000
9.680 558.000 1.000
9.740 561.000 1.000
9.800 564.000 1.000
9.860 576.000 1.000
9.920 546.000 1.000
9.980 570.000 1.000
10.040 577.000 1.000
10.100 555.000 1.000
10.160 563.000 1.000
10.220 568.000 1.000
10.280 574.000 1.000
10.340 586.000 1.000
10.400 590.000 1.000
10.460 596.000 1.000
10.520 573.000 1.000
10.580 581.000 1.000
10.640 602.000 1.000
10.700 593.000 1.000
10.760 585.000 1.000
10.820 614.000 1.000
10.880 556.000 1.000
10.940 597.000 1.000
11.000 602.000 1.000
11.060 599.000 1.000
11.120 589.000 1.000
11.180 616.000 1.000
11.240 605.000 1.000
11.300 633.000 1.000
11.360 602.000 1.000
11.420 608.000 1.000
11.480 607.000 1.000
11.540 612.000 1.000
11.600 613.000 1.000
11.660 607.000 1.000
11.720 640.000 1.000
11.780 609.000 1.000
11.840 644.000 1.000
11.900 625.000 1.000
11.960 621.000 1.000
12.020 608.000 1.000
12.080 605.000 1.000
12.140 658.000 1.000
12.200 628.000 1.000
12.260 652.000 1.000
12.320 621.000 1.000
12.380 634.000 1.000
12.440 651.000 1.000
12.500 640.000 1.000
12.560 645.000 1.000
12.620 634.000 1.000
12.680 647.000 1.000
12.740 628.000 1.000
12.800 658.000 1.000
12.860 655.000 1.000
12.920 629.000 1.000
12.980 644.000 1.000
13.040 664.000 1.000
13.100 625.000 1.000
13.160 632.000 1.000
13.220 643.000 1.000
13.280 638.000 1.000
13.340 639.000 1.000
13.400 645.000 1.000
13.460 640.000 1.000
13.520 652.000 1.000
13.580 647.000 1.000
13.640 614.000 1.000
13.700 640.000 1.000
13.760 672.000 1.000
13.820 642.000 1.000
13.880 639.000 1.000
13.940 634.000 1.000
14.000 620.000 1.000
14.060 683.000 1.000
14.120 679.000 1.000
14.180 658.000 1.000
14.240 688.000 1.000
14.300 669.000 1.000
14.360 670.000 1.000
14.420 633.000 1.000
14.480 680.000 1.000
14.540 690.000 1.000
14.600 704.000 1.000
14.660 689.000 1.000
14.720 728.000 1.000
14.780 692.000 1.000
14.840 717.000 1.000
14.900 693.000 1.000
14.960 719.000 1.000
15.020 776.000 1.000
15.080 809.000 1.000
15.140 975.000 1.000
15.200 1408.000 1.000
15.260 1765.000 1.000
15.320 1597.000 1.000
15.380 1121.000 1.000
15.440 862.000 1.000
15.500 764.000 1.000
15.560 701.000 1.000
15.620 719.000 1.000
15.680 725.000 1.000
15.740 739.000 1.000
15.800 680.000 1.000
15.860 713.000 1.000
15.920 709.000 1.000
15.980 695.000 1.000
16.040 746.000 1.000
16.100 698.000 1.000
16.160 689.000 1.000
16.220 723.000 1.000
16.280 686.000 1.000
16.340 707.000 1.000
16.400 699.000 1.000
16.460 679.000 1.000
16.520 664.000 1.000
16.580 691.000 1.000
16.640 692.000 1.000
16.700 728.000 1.000
16.760 682.000 1.000
16.820 688.000 1.000
16.880 699.000 1.000
16.940 732.000 1.000
17.000 697.000 1.000
17.060 725.000 1.000
17.120 746.000 1.000
17.180 701.000 1.000
17.240 707.000 1.000
17.300 688.000 1.000
17.360 717.000 1.000
17.420 712.000 1.000
17.480 728.000 1.000
17.540 721.000 1.000
17.600 723.000 1.000
17.660 731.000 1.000
17.720 677.000 1.000
17.780 742.000 1.000
17.840 691.000 1.000
17.900 720.000 1.000
17.960 707.000 1.000
18.020 768.000 1.000
18.080 730.000 1.000
18.140 687.000 1.000
18.200 750.000 1.000
18.260 708.000 1.000
18.320 738.000 1.000
18.380 782.000 1.000
18.440 775.000 1.000
18.500 840.000 1.000
18.560 857.000 1.000
18.620 863.000 1.000
18.680 887.000 1.000
18.740 1066.000 1.000
18.800 1620.000 1.000
18.860 3093.000 1.000
18.920 5545.000 1.000
18.980 5027.000 1.000
19.040 2574.000 1.000
19.100 1346.000 1.000
19.160 993.000 1.000
19.220 909.000 1.000
19.280 877.000 1.000
19.340 824.000 1.000
19.400 818.000 1.000
19.460 742.000 1.000
19.520 775.000 1.000
19.580 750.000 1.000
19.640 800.000 1.000
19.700 779.000 1.000
19.760 757.000 1.000
19.820 756.000 1.000
19.880 729.000 1.000
19.940 739.000 1.000
20.000 762.000 1.000
20.060 771.000 1.000
20.120 799.000 1.000
20.180 752.000 1.000
20.240 790.000 1.000
20.300 765.000 1.000
20.360 744.000 1.000
20.420 745.000 1.000
20.480 754.000 1.000
20.540 756.000 1.000
20.600 782.000 1.000
20.660 767.000 1.000
20.720 742.000 1.000
20.780 770.000 1.000
20.840 784.000 1.000
20.900 761.000 1.000
20.960 753.000 1.000
21.020 780.000 1.000
21.080 771.000 1.000
21.140 781.000 1.000
21.200 749.000 1.000
21.260 756.000 1.000
21.320 786.000 1.000
21.380 779.000 1.000
21.440 769.000 1.000
21.500 802.000 1.000
21.560 769.000 1.000
21.620 774.000 1.000
21.680 777.000 1.000
21.740 771.000 1.000
21.800 793.000 1.000
21.860 792.000 1.000
21.920 791.000 1.000
21.980 775.000 1.000
22.040 760.000 1.000
22.100 781.000 1.000
22.160 769.000 1.000
22.220 772.000 1.000
22.280 761.000 1.000
22.340 826.000 1.000
22.400 797.000 1.000
22.460 777.000 1.000
22.520 831.000 1.000
22.580 817.000 1.000
22.640 837.000 1.000
22.700 875.000 1.000
22.760 914.000 1.000
22.820 984.000 1.000
22.880 1065.000 1.000
22.940 1125.000 1.000
23.000 1392.000 1.000
23.060 1584.000 1.000
23.120 1646.000 1.000
23.180 1742.000 1.000
23.240 1750.000 1.000
23.300 1705.000 1.000
23.360 1684.000 1.000
23.420 1911.000 1.000
23.480 2564.000 1.000
23.540 3190.000 1.000
23.600 3079.000 1.000
23.660 2500.000 1.000
23.720 2091.000 1.000
23.780 2016.000 1.000
23.840 2345.000 1.000
23.900 3057.000 1.000
23.960 3195.000 1.000
24.020 2310.000 1.000
24.080 1483.000 1.000
24.140 1121.000 1.000
24.200 1060.000 1.000
24.260 1007.000 1.000
24.320 972.000 1.000
24.380 923.000 1.000
24.440 905.000 1.000
24.500 945.000 1.000
24.560 895.000 1.000
24.620 941.000 1.000
24.680 890.000 1.000
24.740 932.000 1.000
24.800 915.000 1.000
24.860 967.000 1.000
24.920 980.000 1.000
24.980 960.000 1.000
25.040 976.000 1.000
25.100 1001.000 1.000
25.160 1048.000 1.000
25.220 1130.000 1.000
25.280 1186.000 1.000
25.340 1376.000 1.000
25.400 1438.000 1.000
25.460 1764.000 1.000
25.520 2007.000 1.000
25.580 2262.000 1.000
25.640 2446.000 1.000
25.700 2547.000 1.000
25.760 2161.000 1.000
25.820 1704.000 1.000
25.880 1298.000 1.000
25.940 1091.000 1.000
26.000 1015.000 1.000
26.060 897.000 1.000
26.120 915.000 1.000
26.180 957.000 1.000
26.240 891.000 1.000
26.300 871.000 1.000
26.360 876.000 1.000
26.420 879.000 1.000
26.480 875.000 1.000
26.540 908.000 1.000
26.600 881.000 1.000
26.660 908.000 1.000
26.720 933.000 1.000
26.780 905.000 1.000
26.840 949.000 1.000
26.900 915.000 1.000
26.960 885.000 1.000
27.020 882.000 1.000
27.080 865.000 1.000
27.140 886.000 1.000
27.200 859.000 1.000
27.260 865.000 1.000
27.320 856.000 1.000
27.380 868.000 1.000
27.440 872.000 1.000
27.500 876.000 1.000
27.560 861.000 1.000
27.620 841.000 1.000
27.680 866.000 1.000
27.740 875.000 1.000
27.800 889.000 1.000
27.860 861.000 1.000
27.920 867.000 1.000
27.980 890.000 1.000
28.040 914.000 1.000
28.100 911.000 1.000
28.160 922.000 1.000
28.220 941.000 1.000
28.280 952.000 1.000
28.340 965.000 1.000
28.400 982.000 1.000
28.460 1020.000 1.000
28.520 1041.000 1.000
28.580 1196.000 1.000
28.640 1402.000 1.000
28.700 1625.000 1.000
28.760 1938.000 1.000
28.820 2365.000 1.000
28.880 2624.000 1.000
28.940 2916.000 1.000
29.000 3062.000 1.000
29.060 2975.000 1.000
29.120 2836.000 1.000
29.180 2674.000 1.000
29.240 2339.000 1.000
29.300 2149.000 1.000
29.360 2082.000 1.000
29.420 1887.000 1.000
29.480 1690.000 1.000
29.540 1654.000 1.000
29.600 1470.000 1.000
29.660 1474.000 1.000
29.720 1444.000 1.000
29.780 1435.000 1.000
29.840 1465.000 1.000
29.900 1613.000 1.000
29.960 1898.000 1.000
30.020 2937.000 1.000
30.080 4366.000 1.000
30.140 5110.000 1.000
30.200 4516.000 1.000
30.260 3531.000 1.000
30.320 2590.000 1.000
30.380 2049.000 1.000
30.440 1745.000 1.000
30.500 1581.000 1.000
30.560 1465.000 1.000
30.620 1506.000 1.000
30.680 1521.000 1.000
30.740 1779.000 1.000
30.800 2025.000 1.000
30.860 2453.000 1.000
30.920 2751.000 1.000
30.980 2725.000 1.000
31.040 2611.000 1.000
31.100 2595.000 1.000
31.160 2595.000 1.000
31.220 2937.000 1.000
31.280 3342.000 1.000
31.340 3823.000 1.000
31.400 4008.000 1.000
31.460 3634.000 1.000
31.520 2994.000 1.000
31.580 2652.000 1.000
31.640 2557.000 1.000
31.700 2823.000 1.000
31.760 2927.000 1.000
31.820 2909.000 1.000
31.880 2702.000 1.000
31.940 2160.000 1.000
32.000 1742.000 1.000
32.060 1378.000 1.000
32.120 1141.000 1.000
32.180 1114.000 1.000
32.240 1102.000 1.000
32.300 1181.000 1.000
32.360 1299.000 1.000
32.420 1690.000 1.000
32.480 1546.000 1.000
32.540 1317.000 1.000
32.600 1071.000 1.000
32.660 951.000 1.000
32.720 961.000 1.000
32.780 912.000 1.000
32.840 931.000 1.000
32.900 898.000 1.000
32.960 929.000 1.000
33.020 913.000 1.000
33.080 890.000 1.000
33.140 903.000 1.000
33.200 947.000 1.000
33.260 944.000 1.000
33.320 940.000 1.000
33.380 883.000 1.000
33.440 921.000 1.000
33.500 873.000 1.000
33.560 897.000 1.000
33.620 886.000 1.000
33.680 955.000 1.000
33.740 940.000 1.000
33.800 916.000 1.000
33.860 961.000 1.000
33.920 904.000 1.000
33.980 944.000 1.000
34.040 903.000 1.000
34.100 960.000 1.000
34.160 939.000 1.000
34.220 943.000 1.000
34.280 964.000 1.000
34.340 938.000 1.000
34.400 1020.000 1.000
34.460 1034.000 1.000
34.520 1066.000 1.000
34.580 1084.000 1.000
34.640 1075.000 1.000
34.700 1129.000 1.000
34.760 1161.000 1.000
34.820 1183.000 1.000
34.880 1174.000 1.000
34.940 1220.000 1.000
35.000 1256.000 1.000
35.060 1351.000 1.000
35.120 1437.000 1.000
35.180 1575.000 1.000
35.240 1835.000 1.000
35.300 2789.000 1.000
35.360 4295.000 1.000
35.420 6746.000 1.000
35.480 7961.000 1.000
35.540 5984.000 1.000
35.600 4004.000 1.000
35.660 2779.000 1.000
35.720 2631.000 1.000
35.780 2583.000 1.000
35.840 2525.000 1.000
35.900 2243.000 1.000
35.960 2004.000 1.000
36.020 1742.000 1.000
36.080 1650.000 1.000
36.140 1620.000 1.000
36.200 1860.000 1.000
36.260 2360.000 1.000
36.320 2738.000 1.000
36.380 2618.000 1.000
36.440 2281.000 1.000
36.500 2375.000 1.000
36.560 2852.000 1.000
36.620 3392.000 1.000
36.680 3238.000 1.000
36.740 2493.000 1.000
36.800 1800.000 1.000
36.860 1391.000 1.000
36.920 1129.000 1.000
36.980 1116.000 1.000
37.040 1062.000 1.000
37.100 1019.000 1.000
37.160 1014.000 1.000
37.220 991.000 1.000
37.280 986.000 1.000
37.340 1013.000 1.000
37.400 1021.000 1.000
37.460 1016.000 1.000
37.520 1002.000 1.000
37.580 1019.000 1.000
37.640 1016.000 1.000
37.700 1001.000 1.000
37.760 1077.000 1.000
37.820 1059.000 1.000
37.880 1056.000 1.000
37.940 1138.000 1.000
38.000 1145.000 1.000
38.060 1160.000 1.000
38.120 1297.000 1.000
38.180 1359.000 1.000
38.240 1436.000 1.000
38.300 1486.000 1.000
38.360 1757.000 1.000
38.420 2311.000 1.000
38.480 3384.000 1.000
38.540 4680.000 1.000
38.600 5721.000 1.000
38.660 5987.000 1.000
38.720 4667.000 1.000
38.780 3467.000 1.000
38.840 2532.000 1.000
38.900 2057.000 1.000
38.960 1754.000 1.000
39.020 1460.000 1.000
39.080 1270.000 1.000
39.140 1202.000 1.000
39.200 1119.000 1.000
39.260 1091.000 1.000
39.320 1068.000 1.000
39.380 996.000 1.000
39.440 979.000 1.000
39.500 1001.000 1.000
39.560 1015.000 1.000
39.620 1098.000 1.000
39.680 1120.000 1.000
39.740 1136.000 1.000
39.800 1119.000 1.000
39.860 1193.000 1.000
39.920 1178.000 1.000
39.980 1274.000 1.000
40.040 1287.000 1.000
40.100 1272.000 1.000
40.160 1244.000 1.000
40.220 1262.000 1.000
40.280 1149.000 1.000
40.340 1126.000 1.000
40.400 1089.000 1.000
40.460 1067.000 1.000
40.520 1039.000 1.000
40.580 1075.000 1.000
40.640 987.000 1.000
40.700 1012.000 1.000
40.760 1073.000 1.000
40.820 1096.000 1.000
40.880 1200.000 1.000
40.940 1506.000 1.000
41.000 1903.000 1.000
41.060 1963.000 1.000
41.120 1754.000 1.000
41.180 1562.000 1.000
41.240 1226.000 1.000
41.300 1127.000 1.000
41.360 1018.000 1.000
41.420 1036.000 1.000
41.480 1013.000 1.000
41.540 949.000 1.000
41.600 950.000 1.000
41.660 956.000 1.000
41.720 958.000 1.000
41.780 983.000 1.000
41.840 1011.000 1.000
41.900 1006.000 1.000
41.960 1004.000 1.000
42.020 1102.000 1.000
42.080 1052.000 1.000
42.140 1098.000 1.000
42.200 1175.000 1.000
42.260 1155.000 1.000
42.320 1239.000 1.000
42.380 1227.000 1.000
42.440 1254.000 1.000
42.500 1361.000 1.000
42.560 1428.000 1.000
42.620 1457.000 1.000
42.680 1431.000 1.000
42.740 1484.000 1.000
42.800 1368.000 1.000
42.860 1293.000 1.000
42.920 1224.000 1.000
42.980 1191.000 1.000
43.040 1213.000 1.000
43.100 1228.000 1.000
43.160 1216.000 1.000
43.220 1271.000 1.000
43.280 1246.000 1.000
43.340 1203.000 1.000
43.400 1193.000 1.000
43.460 1127.000 1.000
43.520 1085.000 1.000
43.580 1149.000 1.000
43.640 1063.000 1.000
43.700 1091.000 1.000
43.760 1010.000 1.000
43.820 1085.000 1.000
43.880 1068.000 1.000
43.940 1022.000 1.000
44.000 1033.000 1.000
44.060 956.000 1.000
44.120 1014.000 1.000
44.180 988.000 1.000
44.240 979.000 1.000
44.300 1009.000 1.000
44.360 951.000 1.000
44.420 1028.000 1.000
44.480 1066.000 1.000
44.540 1109.000 1.000
44.600 1184.000 1.000
44.660 1203.000 1.000
44.720 1238.000 1.000
44.780 1282.000 1.000
44.840 1309.000 1.000
44.900 1363.000 1.000
44.960 1495.000 1.000
45.020 1547.000 1.000
45.080 1561.000 1.000
45.140 1464.000 1.000
45.200 1366.000 1.000
45.260 1187.000 1.000
45.320 1184.000 1.000
45.380 1127.000 1.000
45.440 1158.000 1.000
45.500 1150.000 1.000
45.560 1149.000 1.000
45.620 1191.000 1.000
45.680 1156.000 1.000
45.740 1128.000 1.000
45.800 1106.000 1.000
45.860 1030.000 1.000
45.920 1024.000 1.000
45.980 1001.000 1.000
46.040 979.000 1.000
46.100 984.000 1.000
46.160 1036.000 1.000
46.220 1005.000 1.000
46.280 977.000 1.000
46.340 978.000 1.000
46.400 983.000 1.000
46.460 939.000 1.000
46.520 963.000 1.000
46.580 971.000 1.000
46.640 983.000 1.000
46.700 1006.000 1.000
46.760 1046.000 1.000
46.820 1029.000 1.000
46.880 1086.000 1.000
46.940 1077.000 1.000
47.000 1105.000 1.000
47.060 1158.000 1.000
47.120 1199.000 1.000
47.180 1220.000 1.000
47.240 1244.000 1.000
47.300 1258.000 1.000
47.360 1287.000 1.000
47.420 1241.000 1.000
47.480 1202.000 1.000
47.540 1234.000 1.000
47.600 1260.000 1.000
47.660 1141.000 1.000
47.720 1180.000 1.000
47.780 1156.000 1.000
47.840 1074.000 1.000
47.900 1096.000 1.000
47.960 1077.000 1.000
48.020 1093.000 1.000
48.080 1129.000 1.000
48.140 1170.000 1.000
48.200 1202.000 1.000
48.260 1288.000 1.000
48.320 1361.000 1.000
48.380 1343.000 1.000
48.440 1315.000 1.000
48.500 1324.000 1.000
48.560 1404.000 1.000
48.620 1554.000 1.000
48.680 1673.000 1.000
48.740 1631.000 1.000
48.800 1579.000 1.000
48.860 1467.000 1.000
48.920 1423.000 1.000
48.980 1540.000 1.000
49.040 1561.000 1.000
49.100 1663.000 1.000
49.160 1653.000 1.000
49.220 1587.000 1.000
49.280 1503.000 1.000
49.340 1440.000 1.000
49.400 1372.000 1.000
49.460 1323.000 1.000
49.520 1247.000 1.000
49.580 1243.000 1.000
49.640 1231.000 1.000
49.700 1183.000 1.000
49.760 1166.000 1.000
49.820 1127.000 1.000
49.880 1129.000 1.000
49.940 1146.000 1.000
50.000 1123.000 1.000
50.060 1141.000 1.000
50.120 1133.000 1.000
50.180 1119.000 1.000
50.240 1149.000 1.000
50.300 1171.000 1.000
50.360 1166.000 1.000
50.420 1188.000 1.000
50.480 1181.000 1.000
50.540 1136.000 1.000
50.600 1174.000 1.000
50.660 1183.000 1.000
50.720 1144.000 1.000
50.780 1121.000 1.000
50.840 1123.000 1.000
50.900 1105.000 1.000
50.960 1100.000 1.000
51.020 1091.000 1.000
51.080 1103.000 1.000
51.140 1093.000 1.000
51.200 1094.000 1.000
51.260 1119.000 1.000
51.320 1122.000 1.000
51.380 1119.000 1.000
51.440 1101.000 1.000
51.500 1078.000 1.000
51.560 1107.000 1.000
51.620 1162.000 1.000
51.680 1209.000 1.000
51.740 1250.000 1.000
51.800 1311.000 1.000
51.860 1300.000 1.000
51.920 1310.000 1.000
51.980 1358.000 1.000
52.040 1328.000 1.000
52.100 1326.000 1.000
52.160 1354.000 1.000
52.220 1299.000 1.000
52.280 1329.000 1.000
52.340 1386.000 1.000
52.400 1345.000 1.000
52.460 1385.000 1.000
52.520 1296.000 1.000
52.580 1295.000 1.000
52.640 1347.000 1.000
52.700 1305.000 1.000
52.760 1287.000 1.000
52.820 1398.000 1.000
52.880 1414.000 1.000
52.940 1475.000 1.000
53.000 1546.000 1.000
53.060 1731.000 1.000
53.120 1972.000 1.000
53.180 2274.000 1.000
53.240 2610.000 1.000
53.300 2942.000 1.000
53.360 3180.000 1.000
53.420 3149.000 1.000
53.480 2799.000 1.000
53.540 2418.000 1.000
53.600 1937.000 1.000
53.660 1611.000 1.000
53.720 1447.000 1.000
53.780 1269.000 1.000
53.840 1222.000 1.000
53.900 1153.000 1.000
53.960 1140.000 1.000
54.020 1104.000 1.000
54.080 1072.000 1.000
54.140 1065.000 1.000
54.200 1058.000 1.000
54.260 1040.000 1.000
54.320 984.000 1.000
54.380 1003.000 1.000
54.440 1005.000 1.000
54.500 1003.000 1.000
54.560 1041.000 1.000
54.620 1032.000 1.000
54.680 1026.000 1.000
54.740 1113.000 1.000
54.800 1136.000 1.000
54.860 1198.000 1.000
54.920 1211.000 1.000
54.980 1278.000 1.000
55.040 1398.000 1.000
55.100 1443.000 1.000
55.160 1531.000 1.000
55.220 1579.000 1.000
55.280 1535.000 1.000
55.340 1537.000 1.000
55.400 1434.000 1.000
55.460 1350.000 1.000
55.520 1238.000 1.000
55.580 1190.000 1.000
55.640 1200.000 1.000
55.700 1177.000 1.000
55.760 1190.000 1.000
55.820 1231.000 1.000
55.880 1249.000 1.000
55.940 1328.000 1.000
56.000 1317.000 1.000
56.060 1410.000 1.000
56.120 1408.000 1.000
56.180 1424.000 1.000
56.240 1405.000 1.000
56.300 1391.000 1.000
56.360 1366.000 1.000
56.420 1293.000 1.000
56.480 1313.000 1.000
56.540 1293.000 1.000
56.600 1352.000 1.000
56.660 1356.000 1.000
56.720 1301.000 1.000
56.780 1304.000 1.000
56.840 1244.000 1.000
56.900 1140.000 1.000
56.960 1072.000 1.000
57.020 1066.000 1.000
57.080 1060.000 1.000
57.140 1065.000 1.000
57.200 1030.000 1.000
57.260 1026.000 1.000
57.320 993.000 1.000
57.380 986.000 1.000
57.440 1003.000 1.000
57.500 1009.000 1.000
57.560 949.000 1.000
57.620 943.000 1.000
57.680 946.000 1.000
57.740 913.000 1.000
57.800 970.000 1.000
57.860 951.000 1.000
57.920 989.000 1.000
57.980 1053.000 1.000
58.040 1043.000 1.000
58.100 1099.000 1.000
58.160 1161.000 1.000
58.220 1183.000 1.000
58.280 1238.000 1.000
58.340 1229.000 1.000
58.400 1250.000 1.000
58.460 1215.000 1.000
58.520 1118.000 1.000
58.580 1100.000 1.000
58.640 1123.000 1.000
58.700 1059.000 1.000
58.760 1067.000 1.000
58.820 1069.000 1.000
58.880 1105.000 1.000
58.940 1084.000 1.000
59.000 1107.000 1.000
59.060 1084.000 1.000
59.120 1101.000 1.000
59.180 1095.000 1.000
59.240 1085.000 1.000
59.300 1071.000 1.000
59.360 1082.000 1.000
59.420 1066.000 1.000
59.480 1080.000 1.000
59.540 1060.000 1.000
59.600 1005.000 1.000
59.660 1035.000 1.000
59.720 1014.000 1.000
59.780 1050.000 1.000
59.840 1008.000 1.000
59.900 988.000 1.000
59.960 972.000 1.000
60.020 981.000 1.000
60.080 1015.000 1.000
60.140 1011.000 1.000
60.200 1049.000 1.000
60.260 1057.000 1.000
60.320 1019.000 1.000
60.380 1061.000 1.000
60.440 1074.000 1.000
60.500 1108.000 1.000
60.560 1167.000 1.000
60.620 1194.000 1.000
60.680 1289.000 1.000
60.740 1380.000 1.000
60.800 1373.000 1.000
60.860 1388.000 1.000
60.920 1381.000 1.000
60.980 1315.000 1.000
61.040 1338.000 1.000
61.100 1300.000 1.000
61.160 1308.000 1.000
61.220 1241.000 1.000
61.280 1261.000 1.000
61.340 1318.000 1.000
61.400 1565.000 1.000
61.460 1687.000 1.000
61.520 1545.000 1.000
61.580 1571.000 1.000
61.640 1505.000 1.000
61.700 1417.000 1.000
61.760 1317.000 1.000
61.820 1272.000 1.000
61.880 1245.000 1.000
61.940 1319.000 1.000
62.000 1262.000 1.000
62.060 1303.000 1.000
62.120 1308.000 1.000
62.180 1343.000 1.000
62.240 1378.000 1.000
62.300 1444.000 1.000
62.360 1505.000 1.000
62.420 1619.000 1.000
62.480 1617.000 1.000
62.540 1768.000 1.000
62.600 1852.000 1.000
62.660 1864.000 1.000
62.720 1801.000 1.000
62.780 1716.000 1.000
62.840 1612.000 1.000
62.900 1565.000 1.000
62.960 1452.000 1.000
63.020 1444.000 1.000
63.080 1355.000 1.000
63.140 1347.000 1.000
63.200 1348.000 1.000
63.260 1393.000 1.000
63.320 1385.000 1.000
63.380 1349.000 1.000
63.440 1317.000 1.000
63.500 1291.000 1.000
63.560 1240.000 1.000
63.620 1272.000 1.000
63.680 1216.000 1.000
63.740 1315.000 1.000
63.800 1366.000 1.000
63.860 1467.000 1.000
63.920 1517.000 1.000
63.980 1556.000 1.000
64.040 1548.000 1.000
64.100 1481.000 1.000
64.160 1466.000 1.000
64.220 1425.000 1.000
64.280 1326.000 1.000
64.340 1293.000 1.000
64.400 1262.000 1.000
64.460 1211.000 1.000
64.520 1182.000 1.000
64.580 1171.000 1.000
64.640 1199.000 1.000
64.700 1170.000 1.000
64.760 1133.000 1.000
64.820 1170.000 1.000
64.880 1171.000 1.000
64.940 1225.000 1.000
65.000 1241.000 1.000
65.060 1347.000 1.000
65.120 1512.000 1.000
65.180 1445.000 1.000
65.240 1411.000 1.000
65.300 1458.000 1.000
65.360 1421.000 1.000
65.420 1389.000 1.000
65.480 1413.000 1.000
65.540 1516.000 1.000
65.600 1632.000 1.000
65.660 1738.000 1.000
65.720 1867.000 1.000
65.780 1874.000 1.000
65.840 1864.000 1.000
65.900 1888.000 1.000
65.960 1915.000 1.000
66.020 1881.000 1.000
66.080 2019.000 1.000
66.140 2172.000 1.000
66.200 2164.000 1.000
66.260 2140.000 1.000
66.320 2096.000 1.000
66.380 1971.000 1.000
66.440 1809.000 1.000
66.500 1711.000 1.000
66.560 1593.000 1.000
66.620 1536.000 1.000
66.680 1387.000 1.000
66.740 1336.000 1.000
66.800 1301.000 1.000
66.860 1269.000 1.000
66.920 1265.000 1.000
66.980 1229.000 1.000
67.040 1232.000 1.000
67.100 1267.000 1.000
67.160 1240.000 1.000
67.220 1301.000 1.000
67.280 1268.000 1.000
67.340 1272.000 1.000
67.400 1269.000 1.000
67.460 1237.000 1.000
67.520 1256.000 1.000
67.580 1310.000 1.000
67.640 1285.000 1.000
67.700 1363.000 1.000
67.760 1462.000 1.000
67.820 1578.000 1.000
67.880 1726.000 1.000
67.940 2018.000 1.000
68.000 2299.000 1.000
68.060 2128.000 1.000
68.120 1839.000 1.000
68.180 1797.000 1.000
68.240 1641.000 1.000
68.300 1429.000 1.000
68.360 1159.000 1.000
68.420 1140.000 1.000
68.480 1047.000 1.000
68.540 1040.000 1.000
68.600 988.000 1.000
68.660 1008.000 1.000
68.720 1004.000 1.000
68.780 997.000 1.000
68.840 1010.000 1.000
68.900 1003.000 1.000
68.960 1018.000 1.000
69.020 1015.000 1.000
69.080 1026.000 1.000
69.140 1011.000 1.000
69.200 1041.000 1.000
69.260 1043.000 1.000
69.320 1000.000 1.000
69.380 983.000 1.000
69.440 1001.000 1.000
69.500 996.000 1.000
69.560 1007.000 1.000
69.620 1038.000 1.000
69.680 989.000 1.000
69.740 1015.000 1.000
69.800 998.000 1.000
69.860 1045.000 1.000
69.920 1001.000 1.000
69.980 1039.000 1.000
70.040 1038.000 1.000
70.100 1052.000 1.000
70.160 1043.000 1.000
70.220 1028.000 1.000
70.280 1041.000 1.000
70.340 1054.000 1.000
70.400 1011.000 1.000
70.460 1051.000 1.000
70.520 986.000 1.000
70.580 979.000 1.000
70.640 941.000 1.000
70.700 1011.000 1.000
70.760 976.000 1.000
70.820 954.000 1.000
70.880 973.000 1.000
70.940 1001.000 1.000
71.000 932.000 1.000
71.060 954.000 1.000
71.120 978.000 1.000
71.180 941.000 1.000
71.240 933.000 1.000
71.300 997.000 1.000
71.360 965.000 1.000
71.420 930.000 1.000
71.480 970.000 1.000
71.540 1001.000 1.000
71.600 963.000 1.000
71.660 961.000 1.000
71.720 957.000 1.000
71.780 948.000 1.000
71.840 985.000 1.000
71.900 952.000 1.000
71.960 932.000 1.000
72.020 929.000 1.000
72.080 1001.000 1.000
72.140 1041.000 1.000
72.200 1051.000 1.000
72.260 1097.000 1.000
72.320 1085.000 1.000
72.380 1125.000 1.000
72.440 1021.000 1.000
72.500 1117.000 1.000
72.560 1079.000 1.000
72.620 1085.000 1.000
72.680 1132.000 1.000
72.740 1104.000 1.000
72.800 1112.000 1.000
72.860 1175.000 1.000
72.920 1124.000 1.000
72.980 1182.000 1.000
73.040 1161.000 1.000
73.100 1190.000 1.000
73.160 1134.000 1.000
73.220 1109.000 1.000
73.280 1095.000 1.000
73.340 1081.000 1.000
73.400 1039.000 1.000
73.460 1050.000 1.000
73.520 1009.000 1.000
73.580 982.000 1.000
73.640 1047.000 1.000
73.700 1003.000 1.000
73.760 992.000 1.000
73.820 1002.000 1.000
73.880 1055.000 1.000
73.940 1006.000 1.000
74.000 1043.000 1.000
74.060 1029.000 1.000
74.120 1046.000 1.000
74.180 1048.000 1.000
74.240 1056.000 1.000
74.300 1065.000 1.000
74.360 1051.000 1.000
74.420 1105.000 1.000
74.480 1152.000 1.000
74.540 1112.000 1.000
74.600 1204.000 1.000
74.660 1193.000 1.000
74.720 1163.000 1.000
74.780 1206.000 1.000
74.840 1238.000 1.000
74.900 1291.000 1.000
74.960 1294.000 1.000
75.020 1265.000 1.000
75.080 1388.000 1.000
75.140 1455.000 1.000
75.200 1363.000 1.000
75.260 1285.000 1.000
75.320 1277.000 1.000
75.380 1252.000 1.000
75.440 1176.000 1.000
75.500 1114.000 1.000
75.560 1108.000 1.000
75.620 1022.000 1.000
75.680 1062.000 1.000
75.740 995.000 1.000
75.800 1030.000 1.000
75.860 1038.000 1.000
75.920 1053.000 1.000
75.980 994.000 1.000
76.040 984.000 1.000
76.100 1022.000 1.000
76.160 1006.000 1.000
76.220 986.000 1.000
76.280 1058.000 1.000
76.340 1019.000 1.000
76.400 1008.000 1.000
76.460 1055.000 1.000
76.520 1027.000 1.000
76.580 1044.000 1.000
76.640 1003.000 1.000
76.700 1031.000 1.000
76.760 1015.000 1.000
76.820 1050.000 1.000
76.880 1040.000 1.000
76.940 1064.000 1.000
77.000 1043.000 1.000
77.060 1020.000 1.000
77.120 1038.000 1.000
77.180 1020.000 1.000
77.240 1016.000 1.000
77.300 1071.000 1.000
77.360 977.000 1.000
77.420 1020.000 1.000
77.480 1011.000 1.000
77.540 1060.000 1.000
77.600 1041.000 1.000
77.660 1002.000 1.000
77.720 1036.000 1.000
77.780 1059.000 1.000
77.840 1095.000 1.000
77.900 1107.000 1.000
77.960 1116.000 1.000
78.020 1136.000 1.000
78.080 1118.000 1.000
78.140 1117.000 1.000
78.200 1058.000 1.000
78.260 1107.000 1.000
78.320 1104.000 1.000
78.380 1046.000 1.000
78.440 1033.000 1.000
78.500 1056.000 1.000
78.560 987.000 1.000
78.620 1030.000 1.000
78.680 1009.000 1.000
78.740 970.000 1.000
78.800 992.000 1.000
78.860 943.000 1.000
78.920 987.000 1.000
78.980 985.000 1.000
79.040 950.000 1.000
79.100 932.000 1.000
79.160 974.000 1.000
79.220 928.000 1.000
79.280 971.000 1.000
79.340 928.000 1.000
79.400 941.000 1.000
79.460 906.000 1.000
79.520 932.000 1.000
79.580 958.000 1.000
79.640 940.000 1.000
79.700 936.000 1.000
79.760 963.000 1.000
79.820 985.000 1.000
79.880 959.000 1.000
79.940 992.000 1.000
80.000 1042.000 1.000
80.060 1043.000 1.000
80.120 1019.000 1.000
80.180 1013.000 1.000
80.240 1036.000 1.000
80.300 1018.000 1.000
80.360 989.000 1.000
80.420 1011.000 1.000
80.480 970.000 1.000
80.540 989.000 1.000
80.600 942.000 1.000
80.660 993.000 1.000
80.720 997.000 1.000
80.780 968.000 1.000
80.840 931.000 1.000
80.900 952.000 1.000
80.960 934.000 1.000
81.020 931.000 1.000
81.080 939.000 1.000
81.140 960.000 1.000
81.200 971.000 1.000
81.260 949.000 1.000
81.320 926.000 1.000
81.380 908.000 1.000
81.440 985.000 1.000
81.500 981.000 1.000
81.560 977.000 1.000
81.620 1048.000 1.000
81.680 1047.000 1.000
81.740 1074.000 1.000
81.800 1066.000 1.000
81.860 1035.000 1.000
81.920 1059.000 1.000
81.980 1039.000 1.000
82.040 988.000 1.000
82.100 1051.000 1.000
82.160 1034.000 1.000
82.220 1091.000 1.000
82.280 1115.000 1.000
82.340 1119.000 1.000
82.400 1114.000 1.000
82.460 1122.000 1.000
82.520 1129.000 1.000
82.580 1176.000 1.000
82.640 1162.000 1.000
82.700 1176.000 1.000
82.760 1224.000 1.000
82.820 1162.000 1.000
82.880 1217.000 1.000
82.940 1185.000 1.000
83.000 1172.000 1.000
83.060 1133.000 1.000
83.120 1145.000 1.000
83.180 1109.000 1.000
83.240 1094.000 1.000
83.300 1098.000 1.000
83.360 1047.000 1.000
83.420 1097.000 1.000
83.480 1155.000 1.000
83.540 1119.000 1.000
83.600 1138.000 1.000
83.660 1097.000 1.000
83.720 1133.000 1.000
83.780 1157.000 1.000
83.840 1126.000 1.000
83.900 1104.000 1.000
83.960 1142.000 1.000
84.020 1106.000 1.000
84.080 1116.000 1.000
84.140 1115.000 1.000
84.200 1132.000 1.000
84.260 1119.000 1.000
84.320 1118.000 1.000
84.380 1108.000 1.000
84.440 1101.000 1.000
84.500 1155.000 1.000
84.560 1145.000 1.000
84.620 1124.000 1.000
84.680 1154.000 1.000
84.740 1143.000 1.000
84.800 1112.000 1.000
84.860 1113.000 1.000
84.920 1108.000 1.000
84.980 1085.000 1.000
85.040 1111.000 1.000
85.100 1050.000 1.000
85.160 1117.000 1.000
85.220 1057.000 1.000
85.280 1048.000 1.000
85.340 1031.000 1.000
85.400 1004.000 1.000
85.460 1031.000 1.000
85.520 1005.000 1.000
85.580 974.000 1.000
85.640 1004.000 1.000
85.700 1023.000 1.000
85.760 1033.000 1.000
85.820 1004.000 1.000
85.880 1017.000 1.000
85.940 1064.000 1.000
86.000 1041.000 1.000
86.060 1006.000 1.000
86.120 988.000 1.000
86.180 1073.000 1.000
86.240 1042.000 1.000
86.300 1049.000 1.000
86.360 1019.000 1.000
86.420 1100.000 1.000
86.480 1054.000 1.000
86.540 1109.000 1.000
86.600 1053.000 1.000
86.660 1065.000 1.000
86.720 1120.000 1.000
86.780 1065.000 1.000
86.840 1143.000 1.000
86.900 1078.000 1.000
86.960 1073.000 1.000
87.020 1111.000 1.000
87.080 1039.000 1.000
87.140 1089.000 1.000
87.200 1100.000 1.000
87.260 1055.000 1.000
87.320 1083.000 1.000
87.380 1017.000 1.000
87.440 1061.000 1.000
87.500 1053.000 1.000
87.560 1053.000 1.000
87.620 983.000 1.000
87.680 1024.000 1.000
87.740 1020.000 1.000
87.800 1050.000 1.000
87.860 1055.000 1.000
87.920 1057.000 1.000
87.980 1044.000 1.000
88.040 1100.000 1.000
88.100 1075.000 1.000
88.160 1018.000 1.000
88.220 1016.000 1.000
88.280 1057.000 1.000
88.340 1051.000 1.000
88.400 1013.000 1.000
88.460 1083.000 1.000
88.520 1025.000 1.000
88.580 1038.000 1.000
88.640 1101.000 1.000
88.700 1129.000 1.000
88.760 1130.000 1.000
88.820 1103.000 1.000
88.880 1154.000 1.000
88.940 1142.000 1.000
89.000 1172.000 1.000
89.060 1217.000 1.000
89.120 1224.000 1.000
89.180 1175.000 1.000
89.240 1174.000 1.000
89.300 1172.000 1.000
89.360 1182.000 1.000
89.420 1191.000 1.000
89.480 1280.000 1.000
89.540 1269.000 1.000
89.600 1332.000 1.000
89.660 1359.000 1.000
89.720 1441.000 1.000
89.780 1353.000 1.000
89.840 1347.000 1.000
89.900 1248.000 1.000
89.960 1265.000 1.000
90.000 1265.000 1.000
*RAS_INT_END
*RAS_DATA_END